Watching for file changes with StatReloader
Session data corrupted
Session data corrupted
Internal Server Error: /package/5/process_booking/
Traceback (most recent call last):
  File "/home/jobina/Documents/minproject/DRMS/DjangoV/lib/python3.10/site-packages/django/core/handlers/exception.py", line 55, in inner
    response = get_response(request)
  File "/home/jobina/Documents/minproject/DRMS/DjangoV/lib/python3.10/site-packages/django/core/handlers/base.py", line 197, in _get_response
    response = wrapped_callback(request, *callback_args, **callback_kwargs)
  File "/home/jobina/Documents/minproject/DRMS/DjangoV/lib/python3.10/site-packages/django/views/decorators/http.py", line 64, in inner
    return func(request, *args, **kwargs)
  File "/usr/lib/python3.10/contextlib.py", line 79, in inner
    return func(*args, **kwds)
  File "/home/jobina/Documents/minproject/DRMS/daycation/adminpanal/views.py", line 772, in process_booking
    total_price = package.price * (num_adults + (num_children * 0.5))
TypeError: unsupported operand type(s) for *: 'decimal.Decimal' and 'float'
/home/jobina/Documents/minproject/DRMS/daycation/daycation/settings.py changed, reloading.
Watching for file changes with StatReloader
/home/jobina/Documents/minproject/DRMS/daycation/daycation/settings.py changed, reloading.
Watching for file changes with StatReloader
/home/jobina/Documents/minproject/DRMS/daycation/daycation/settings.py changed, reloading.
Watching for file changes with StatReloader
/home/jobina/Documents/minproject/DRMS/daycation/adminpanal/views.py changed, reloading.
Watching for file changes with StatReloader
/home/jobina/Documents/minproject/DRMS/daycation/adminpanal/views.py changed, reloading.
Watching for file changes with StatReloader
/home/jobina/Documents/minproject/DRMS/daycation/adminpanal/views.py changed, reloading.
Watching for file changes with StatReloader
/home/jobina/Documents/minproject/DRMS/daycation/adminpanal/views.py changed, reloading.
Watching for file changes with StatReloader
/home/jobina/Documents/minproject/DRMS/daycation/adminpanal/views.py changed, reloading.
Watching for file changes with StatReloader
/home/jobina/Documents/minproject/DRMS/daycation/adminpanal/views.py changed, reloading.
Watching for file changes with StatReloader
/home/jobina/Documents/minproject/DRMS/daycation/adminpanal/views.py changed, reloading.
Watching for file changes with StatReloader
/home/jobina/Documents/minproject/DRMS/daycation/adminpanal/views.py changed, reloading.
Watching for file changes with StatReloader
/home/jobina/Documents/minproject/DRMS/daycation/adminpanal/views.py changed, reloading.
Watching for file changes with StatReloader
/home/jobina/Documents/minproject/DRMS/daycation/adminpanal/views.py changed, reloading.
Watching for file changes with StatReloader
/home/jobina/Documents/minproject/DRMS/daycation/adminpanal/views.py changed, reloading.
Watching for file changes with StatReloader
/home/jobina/Documents/minproject/DRMS/daycation/adminpanal/views.py changed, reloading.
Watching for file changes with StatReloader
Session data corrupted
Starting new HTTPS connection (1): oauth2.googleapis.com:443
https://oauth2.googleapis.com:443 "POST /token HTTP/11" 200 None
Internal Server Error: /daycation/5/
Traceback (most recent call last):
  File "/home/jobina/Documents/minproject/DRMS/DjangoV/lib/python3.10/site-packages/django/core/handlers/exception.py", line 55, in inner
    response = get_response(request)
  File "/home/jobina/Documents/minproject/DRMS/DjangoV/lib/python3.10/site-packages/django/core/handlers/base.py", line 197, in _get_response
    response = wrapped_callback(request, *callback_args, **callback_kwargs)
  File "/home/jobina/Documents/minproject/DRMS/daycation/adminpanal/views.py", line 537, in daycation_package_details
    future_bookings = DaycationBooking.objects.filter(
  File "/home/jobina/Documents/minproject/DRMS/DjangoV/lib/python3.10/site-packages/django/db/models/query.py", line 1630, in annotate
    return self._annotate(args, kwargs, select=True)
  File "/home/jobina/Documents/minproject/DRMS/DjangoV/lib/python3.10/site-packages/django/db/models/query.py", line 1680, in _annotate
    clone.query.add_annotation(
  File "/home/jobina/Documents/minproject/DRMS/DjangoV/lib/python3.10/site-packages/django/db/models/sql/query.py", line 1194, in add_annotation
    annotation = annotation.resolve_expression(self, allow_joins=True, reuse=None)
  File "/home/jobina/Documents/minproject/DRMS/DjangoV/lib/python3.10/site-packages/django/db/models/aggregates.py", line 63, in resolve_expression
    c = super().resolve_expression(query, allow_joins, reuse, summarize)
  File "/home/jobina/Documents/minproject/DRMS/DjangoV/lib/python3.10/site-packages/django/db/models/expressions.py", line 1073, in resolve_expression
    c.source_expressions[pos] = arg.resolve_expression(
  File "/home/jobina/Documents/minproject/DRMS/DjangoV/lib/python3.10/site-packages/django/db/models/expressions.py", line 895, in resolve_expression
    return query.resolve_ref(self.name, allow_joins, reuse, summarize)
  File "/home/jobina/Documents/minproject/DRMS/DjangoV/lib/python3.10/site-packages/django/db/models/sql/query.py", line 2010, in resolve_ref
    join_info = self.setup_joins(
  File "/home/jobina/Documents/minproject/DRMS/DjangoV/lib/python3.10/site-packages/django/db/models/sql/query.py", line 1863, in setup_joins
    path, final_field, targets, rest = self.names_to_path(
  File "/home/jobina/Documents/minproject/DRMS/DjangoV/lib/python3.10/site-packages/django/db/models/sql/query.py", line 1768, in names_to_path
    raise FieldError(
django.core.exceptions.FieldError: Cannot resolve keyword 'guests' into field. Choices are: addons, address, created_at, date, email, food_preference, full_name, id, num_adults, num_children, package, package_id, payment_status, phone, razorpay_order_id, razorpay_payment_id, razorpay_signature, special_requests, status, total_price, user, user_id
/home/jobina/Documents/minproject/DRMS/daycation/adminpanal/views.py changed, reloading.
Watching for file changes with StatReloader
/home/jobina/Documents/minproject/DRMS/daycation/adminpanal/views.py changed, reloading.
Watching for file changes with StatReloader
/home/jobina/Documents/minproject/DRMS/daycation/adminpanal/views.py changed, reloading.
Watching for file changes with StatReloader
/home/jobina/Documents/minproject/DRMS/daycation/adminpanal/views.py changed, reloading.
Watching for file changes with StatReloader
/home/jobina/Documents/minproject/DRMS/daycation/adminpanal/views.py changed, reloading.
Watching for file changes with StatReloader
/home/jobina/Documents/minproject/DRMS/daycation/adminpanal/views.py changed, reloading.
Watching for file changes with StatReloader
/home/jobina/Documents/minproject/DRMS/daycation/adminpanal/views.py changed, reloading.
Watching for file changes with StatReloader
/home/jobina/Documents/minproject/DRMS/daycation/adminpanal/views.py changed, reloading.
Watching for file changes with StatReloader
Session data corrupted
Session data corrupted
Session data corrupted
Internal Server Error: /package/5/process_booking/
Traceback (most recent call last):
  File "/home/jobina/Documents/minproject/DRMS/DjangoV/lib/python3.10/site-packages/django/core/handlers/exception.py", line 55, in inner
    response = get_response(request)
  File "/home/jobina/Documents/minproject/DRMS/DjangoV/lib/python3.10/site-packages/django/core/handlers/base.py", line 197, in _get_response
    response = wrapped_callback(request, *callback_args, **callback_kwargs)
  File "/home/jobina/Documents/minproject/DRMS/DjangoV/lib/python3.10/site-packages/django/views/decorators/http.py", line 64, in inner
    return func(request, *args, **kwargs)
  File "/usr/lib/python3.10/contextlib.py", line 79, in inner
    return func(*args, **kwds)
  File "/home/jobina/Documents/minproject/DRMS/daycation/adminpanal/views.py", line 773, in process_booking
    total_price = package.price * (num_adults + (num_children * 0.5))
TypeError: unsupported operand type(s) for *: 'decimal.Decimal' and 'float'
Session data corrupted
Internal Server Error: /package/5/process_booking/
Traceback (most recent call last):
  File "/home/jobina/Documents/minproject/DRMS/DjangoV/lib/python3.10/site-packages/django/core/handlers/exception.py", line 55, in inner
    response = get_response(request)
  File "/home/jobina/Documents/minproject/DRMS/DjangoV/lib/python3.10/site-packages/django/core/handlers/base.py", line 197, in _get_response
    response = wrapped_callback(request, *callback_args, **callback_kwargs)
  File "/home/jobina/Documents/minproject/DRMS/DjangoV/lib/python3.10/site-packages/django/views/decorators/http.py", line 64, in inner
    return func(request, *args, **kwargs)
  File "/usr/lib/python3.10/contextlib.py", line 79, in inner
    return func(*args, **kwds)
  File "/home/jobina/Documents/minproject/DRMS/daycation/adminpanal/views.py", line 773, in process_booking
    total_price = package.price * (num_adults + (num_children * 0.5))
TypeError: unsupported operand type(s) for *: 'decimal.Decimal' and 'float'
/home/jobina/Documents/minproject/DRMS/daycation/adminpanal/views.py changed, reloading.
Watching for file changes with StatReloader
Session data corrupted
Session data corrupted
Internal Server Error: /package/5/process_booking/
Traceback (most recent call last):
  File "/home/jobina/Documents/minproject/DRMS/DjangoV/lib/python3.10/site-packages/django/core/handlers/exception.py", line 55, in inner
    response = get_response(request)
  File "/home/jobina/Documents/minproject/DRMS/DjangoV/lib/python3.10/site-packages/django/core/handlers/base.py", line 197, in _get_response
    response = wrapped_callback(request, *callback_args, **callback_kwargs)
  File "/home/jobina/Documents/minproject/DRMS/DjangoV/lib/python3.10/site-packages/django/views/decorators/http.py", line 64, in inner
    return func(request, *args, **kwargs)
  File "/usr/lib/python3.10/contextlib.py", line 79, in inner
    return func(*args, **kwds)
  File "/home/jobina/Documents/minproject/DRMS/daycation/adminpanal/views.py", line 773, in process_booking
    total_price = package.price * (num_adults + (num_children * 0.5))
TypeError: unsupported operand type(s) for *: 'decimal.Decimal' and 'float'
/home/jobina/Documents/minproject/DRMS/daycation/daycation/settings.py changed, reloading.
Watching for file changes with StatReloader
/home/jobina/Documents/minproject/DRMS/daycation/daycation/settings.py changed, reloading.
Watching for file changes with StatReloader
/home/jobina/Documents/minproject/DRMS/daycation/adminpanal/views.py changed, reloading.
Watching for file changes with StatReloader
Session data corrupted
Session data corrupted
Internal Server Error: /package/5/process_booking/
Traceback (most recent call last):
  File "/home/jobina/Documents/minproject/DRMS/DjangoV/lib/python3.10/site-packages/django/core/handlers/exception.py", line 55, in inner
    response = get_response(request)
  File "/home/jobina/Documents/minproject/DRMS/DjangoV/lib/python3.10/site-packages/django/core/handlers/base.py", line 197, in _get_response
    response = wrapped_callback(request, *callback_args, **callback_kwargs)
  File "/home/jobina/Documents/minproject/DRMS/DjangoV/lib/python3.10/site-packages/django/views/decorators/http.py", line 64, in inner
    return func(request, *args, **kwargs)
  File "/usr/lib/python3.10/contextlib.py", line 79, in inner
    return func(*args, **kwds)
  File "/home/jobina/Documents/minproject/DRMS/daycation/adminpanal/views.py", line 778, in process_booking
    total_price = package.price * (num_adults + (num_children * 0.5))
TypeError: unsupported operand type(s) for *: 'decimal.Decimal' and 'float'
Session data corrupted
Session data corrupted
Internal Server Error: /package/5/process_booking/
Traceback (most recent call last):
  File "/home/jobina/Documents/minproject/DRMS/DjangoV/lib/python3.10/site-packages/django/core/handlers/exception.py", line 55, in inner
    response = get_response(request)
  File "/home/jobina/Documents/minproject/DRMS/DjangoV/lib/python3.10/site-packages/django/core/handlers/base.py", line 197, in _get_response
    response = wrapped_callback(request, *callback_args, **callback_kwargs)
  File "/home/jobina/Documents/minproject/DRMS/DjangoV/lib/python3.10/site-packages/django/views/decorators/http.py", line 64, in inner
    return func(request, *args, **kwargs)
  File "/usr/lib/python3.10/contextlib.py", line 79, in inner
    return func(*args, **kwds)
  File "/home/jobina/Documents/minproject/DRMS/daycation/adminpanal/views.py", line 778, in process_booking
    total_price = package.price * (num_adults + (num_children * 0.5))
TypeError: unsupported operand type(s) for *: 'decimal.Decimal' and 'float'
/home/jobina/Documents/minproject/DRMS/daycation/daycation/settings.py changed, reloading.
Watching for file changes with StatReloader
/home/jobina/Documents/minproject/DRMS/daycation/daycation/settings.py changed, reloading.
Watching for file changes with StatReloader
/home/jobina/Documents/minproject/DRMS/daycation/daycation/settings.py changed, reloading.
Watching for file changes with StatReloader
Session data corrupted
Session data corrupted
Internal Server Error: /package/5/process_booking/
Traceback (most recent call last):
  File "/home/jobina/Documents/minproject/DRMS/DjangoV/lib/python3.10/site-packages/django/core/handlers/exception.py", line 55, in inner
    response = get_response(request)
  File "/home/jobina/Documents/minproject/DRMS/DjangoV/lib/python3.10/site-packages/django/core/handlers/base.py", line 197, in _get_response
    response = wrapped_callback(request, *callback_args, **callback_kwargs)
  File "/home/jobina/Documents/minproject/DRMS/DjangoV/lib/python3.10/site-packages/django/views/decorators/http.py", line 64, in inner
    return func(request, *args, **kwargs)
  File "/usr/lib/python3.10/contextlib.py", line 79, in inner
    return func(*args, **kwds)
  File "/home/jobina/Documents/minproject/DRMS/daycation/adminpanal/views.py", line 778, in process_booking
    total_price = package.price * (num_adults + (num_children * 0.5))
TypeError: unsupported operand type(s) for *: 'decimal.Decimal' and 'float'
/home/jobina/Documents/minproject/DRMS/daycation/adminpanal/views.py changed, reloading.
Watching for file changes with StatReloader
Session data corrupted
Internal Server Error: /package/5/process_booking/
Traceback (most recent call last):
  File "/home/jobina/Documents/minproject/DRMS/DjangoV/lib/python3.10/site-packages/django/core/handlers/exception.py", line 55, in inner
    response = get_response(request)
  File "/home/jobina/Documents/minproject/DRMS/DjangoV/lib/python3.10/site-packages/django/core/handlers/base.py", line 197, in _get_response
    response = wrapped_callback(request, *callback_args, **callback_kwargs)
  File "/home/jobina/Documents/minproject/DRMS/DjangoV/lib/python3.10/site-packages/django/views/decorators/http.py", line 64, in inner
    return func(request, *args, **kwargs)
  File "/usr/lib/python3.10/contextlib.py", line 79, in inner
    return func(*args, **kwds)
  File "/home/jobina/Documents/minproject/DRMS/daycation/adminpanal/views.py", line 781, in process_booking
    total_price = package.price * (num_adults + (num_children * 0.5))
TypeError: unsupported operand type(s) for *: 'decimal.Decimal' and 'float'
Watching for file changes with StatReloader
Not Found: /favicon.ico
Session data corrupted
Session data corrupted
Session data corrupted
Session data corrupted
Session data corrupted
Session data corrupted
Session data corrupted
Session data corrupted
Session data corrupted
Session data corrupted
Internal Server Error: /package/5/process_booking/
Traceback (most recent call last):
  File "/home/jobina/Documents/minproject/DRMS/DjangoV/lib/python3.10/site-packages/django/core/handlers/exception.py", line 55, in inner
    response = get_response(request)
  File "/home/jobina/Documents/minproject/DRMS/DjangoV/lib/python3.10/site-packages/django/core/handlers/base.py", line 197, in _get_response
    response = wrapped_callback(request, *callback_args, **callback_kwargs)
  File "/home/jobina/Documents/minproject/DRMS/DjangoV/lib/python3.10/site-packages/django/views/decorators/http.py", line 64, in inner
    return func(request, *args, **kwargs)
  File "/usr/lib/python3.10/contextlib.py", line 79, in inner
    return func(*args, **kwds)
  File "/home/jobina/Documents/minproject/DRMS/daycation/adminpanal/views.py", line 781, in process_booking
    total_price = package.price * (num_adults + (num_children * 0.5))
TypeError: unsupported operand type(s) for *: 'decimal.Decimal' and 'float'
/home/jobina/Documents/minproject/DRMS/daycation/adminpanal/views.py changed, reloading.
Watching for file changes with StatReloader
Session data corrupted
Processing booking for package 5
Error processing booking: fromisoformat: argument must be str
Traceback (most recent call last):
  File "/home/jobina/Documents/minproject/DRMS/daycation/adminpanal/views.py", line 569, in process_booking
    booking_date = parse_date(booking_date_str)
  File "/home/jobina/Documents/minproject/DRMS/DjangoV/lib/python3.10/site-packages/django/utils/dateparse.py", line 74, in parse_date
    return datetime.date.fromisoformat(value)
TypeError: fromisoformat: argument must be str

Internal Server Error: /package/5/process_booking/
Session data corrupted
Session data corrupted
Session data corrupted
Processing booking for package 5
Error processing booking: fromisoformat: argument must be str
Traceback (most recent call last):
  File "/home/jobina/Documents/minproject/DRMS/daycation/adminpanal/views.py", line 569, in process_booking
    booking_date = parse_date(booking_date_str)
  File "/home/jobina/Documents/minproject/DRMS/DjangoV/lib/python3.10/site-packages/django/utils/dateparse.py", line 74, in parse_date
    return datetime.date.fromisoformat(value)
TypeError: fromisoformat: argument must be str

Internal Server Error: /package/5/process_booking/
Session data corrupted
Session data corrupted
Processing booking for package 5
Error processing booking: fromisoformat: argument must be str
Traceback (most recent call last):
  File "/home/jobina/Documents/minproject/DRMS/daycation/adminpanal/views.py", line 569, in process_booking
    booking_date = parse_date(booking_date_str)
  File "/home/jobina/Documents/minproject/DRMS/DjangoV/lib/python3.10/site-packages/django/utils/dateparse.py", line 74, in parse_date
    return datetime.date.fromisoformat(value)
TypeError: fromisoformat: argument must be str

Internal Server Error: /package/5/process_booking/
Session data corrupted
Processing booking for package 5
Error processing booking: fromisoformat: argument must be str
Traceback (most recent call last):
  File "/home/jobina/Documents/minproject/DRMS/daycation/adminpanal/views.py", line 569, in process_booking
    booking_date = parse_date(booking_date_str)
  File "/home/jobina/Documents/minproject/DRMS/DjangoV/lib/python3.10/site-packages/django/utils/dateparse.py", line 74, in parse_date
    return datetime.date.fromisoformat(value)
TypeError: fromisoformat: argument must be str

Internal Server Error: /package/5/process_booking/
Session data corrupted
Session data corrupted
Processing booking for package 5
Error processing booking: fromisoformat: argument must be str
Traceback (most recent call last):
  File "/home/jobina/Documents/minproject/DRMS/daycation/adminpanal/views.py", line 569, in process_booking
    booking_date = parse_date(booking_date_str)
  File "/home/jobina/Documents/minproject/DRMS/DjangoV/lib/python3.10/site-packages/django/utils/dateparse.py", line 74, in parse_date
    return datetime.date.fromisoformat(value)
TypeError: fromisoformat: argument must be str

Internal Server Error: /package/5/process_booking/
Session data corrupted
Processing booking for package 5
Error processing booking: fromisoformat: argument must be str
Traceback (most recent call last):
  File "/home/jobina/Documents/minproject/DRMS/daycation/adminpanal/views.py", line 569, in process_booking
    booking_date = parse_date(booking_date_str)
  File "/home/jobina/Documents/minproject/DRMS/DjangoV/lib/python3.10/site-packages/django/utils/dateparse.py", line 74, in parse_date
    return datetime.date.fromisoformat(value)
TypeError: fromisoformat: argument must be str

Internal Server Error: /package/5/process_booking/
Session data corrupted
Session data corrupted
Processing booking for package 5
Error processing booking: fromisoformat: argument must be str
Traceback (most recent call last):
  File "/home/jobina/Documents/minproject/DRMS/daycation/adminpanal/views.py", line 569, in process_booking
    booking_date = parse_date(booking_date_str)
  File "/home/jobina/Documents/minproject/DRMS/DjangoV/lib/python3.10/site-packages/django/utils/dateparse.py", line 74, in parse_date
    return datetime.date.fromisoformat(value)
TypeError: fromisoformat: argument must be str

Internal Server Error: /package/5/process_booking/
Watching for file changes with StatReloader
Session data corrupted
Session data corrupted
Processing booking for package 5
Error processing booking: fromisoformat: argument must be str
Traceback (most recent call last):
  File "/home/jobina/Documents/minproject/DRMS/daycation/adminpanal/views.py", line 569, in process_booking
    booking_date = parse_date(booking_date_str)
  File "/home/jobina/Documents/minproject/DRMS/DjangoV/lib/python3.10/site-packages/django/utils/dateparse.py", line 74, in parse_date
    return datetime.date.fromisoformat(value)
TypeError: fromisoformat: argument must be str

Internal Server Error: /package/5/process_booking/
/home/jobina/Documents/minproject/DRMS/daycation/adminpanal/views.py changed, reloading.
Watching for file changes with StatReloader
Session data corrupted
Processing booking for package 5
Session data corrupted
Starting new HTTPS connection (1): api.razorpay.com:443
https://api.razorpay.com:443 "POST /v1/orders HTTP/11" 200 215
Processing booking for package 5
Session data corrupted
https://api.razorpay.com:443 "POST /v1/orders HTTP/11" 200 215
Payment verification failed: DaycationBooking matching query does not exist.
Bad Request: /payment_callback/
Processing booking for package 5
Session data corrupted
https://api.razorpay.com:443 "POST /v1/orders HTTP/11" 200 215
Session data corrupted
Processing booking for package 5
Session data corrupted
https://api.razorpay.com:443 "POST /v1/orders HTTP/11" 200 215
Payment verification failed: DaycationBooking matching query does not exist.
Bad Request: /payment_callback/
/home/jobina/Documents/minproject/DRMS/daycation/adminpanal/views.py changed, reloading.
Watching for file changes with StatReloader
Session data corrupted
Processing booking for package 5
Session data corrupted
Starting new HTTPS connection (1): api.razorpay.com:443
https://api.razorpay.com:443 "POST /v1/orders HTTP/11" 200 213
Processing booking for package 5
Session data corrupted
https://api.razorpay.com:443 "POST /v1/orders HTTP/11" 200 213
/home/jobina/Documents/minproject/DRMS/daycation/adminpanal/views.py changed, reloading.
Watching for file changes with StatReloader
/home/jobina/Documents/minproject/DRMS/daycation/adminpanal/urls.py changed, reloading.
Watching for file changes with StatReloader
/home/jobina/Documents/minproject/DRMS/daycation/adminpanal/views.py changed, reloading.
Watching for file changes with StatReloader
/home/jobina/Documents/minproject/DRMS/daycation/adminpanal/urls.py changed, reloading.
Watching for file changes with StatReloader
Session data corrupted
Processing booking for package 5
Session data corrupted
Starting new HTTPS connection (1): api.razorpay.com:443
https://api.razorpay.com:443 "POST /v1/orders HTTP/11" 200 215
Session data corrupted
Internal Server Error: /verify-payment/
Traceback (most recent call last):
  File "/home/jobina/Documents/minproject/DRMS/DjangoV/lib/python3.10/site-packages/django/core/handlers/exception.py", line 55, in inner
    response = get_response(request)
  File "/home/jobina/Documents/minproject/DRMS/DjangoV/lib/python3.10/site-packages/django/core/handlers/base.py", line 197, in _get_response
    response = wrapped_callback(request, *callback_args, **callback_kwargs)
  File "/home/jobina/Documents/minproject/DRMS/DjangoV/lib/python3.10/site-packages/django/views/decorators/http.py", line 64, in inner
    return func(request, *args, **kwargs)
  File "/home/jobina/Documents/minproject/DRMS/daycation/adminpanal/views.py", line 737, in verify_payment
    payment_data = json.loads(request.body)
NameError: name 'json' is not defined
Watching for file changes with StatReloader
Session data corrupted
Processing booking for package 5
Session data corrupted
Starting new HTTPS connection (1): api.razorpay.com:443
https://api.razorpay.com:443 "POST /v1/orders HTTP/11" 200 215
Session data corrupted
Internal Server Error: /verify-payment/
Traceback (most recent call last):
  File "/home/jobina/Documents/minproject/DRMS/DjangoV/lib/python3.10/site-packages/django/core/handlers/exception.py", line 55, in inner
    response = get_response(request)
  File "/home/jobina/Documents/minproject/DRMS/DjangoV/lib/python3.10/site-packages/django/core/handlers/base.py", line 197, in _get_response
    response = wrapped_callback(request, *callback_args, **callback_kwargs)
  File "/home/jobina/Documents/minproject/DRMS/DjangoV/lib/python3.10/site-packages/django/views/decorators/http.py", line 64, in inner
    return func(request, *args, **kwargs)
  File "/home/jobina/Documents/minproject/DRMS/daycation/adminpanal/views.py", line 737, in verify_payment
    payment_data = json.loads(request.body)
NameError: name 'json' is not defined
Processing booking for package 5
Session data corrupted
https://api.razorpay.com:443 "POST /v1/orders HTTP/11" 200 215
/home/jobina/Documents/minproject/DRMS/daycation/adminpanal/views.py changed, reloading.
Watching for file changes with StatReloader
/home/jobina/Documents/minproject/DRMS/daycation/adminpanal/models.py changed, reloading.
Watching for file changes with StatReloader
Session data corrupted
Processing booking for package 5
Session data corrupted
Error processing booking: (1054, "Unknown column 'updated_at' in 'field list'")
Traceback (most recent call last):
  File "/home/jobina/Documents/minproject/DRMS/DjangoV/lib/python3.10/site-packages/django/db/backends/utils.py", line 105, in _execute
    return self.cursor.execute(sql, params)
  File "/home/jobina/Documents/minproject/DRMS/DjangoV/lib/python3.10/site-packages/django/db/backends/mysql/base.py", line 76, in execute
    return self.cursor.execute(query, args)
  File "/home/jobina/Documents/minproject/DRMS/DjangoV/lib/python3.10/site-packages/pymysql/cursors.py", line 153, in execute
    result = self._query(query)
  File "/home/jobina/Documents/minproject/DRMS/DjangoV/lib/python3.10/site-packages/pymysql/cursors.py", line 322, in _query
    conn.query(q)
  File "/home/jobina/Documents/minproject/DRMS/DjangoV/lib/python3.10/site-packages/pymysql/connections.py", line 563, in query
    self._affected_rows = self._read_query_result(unbuffered=unbuffered)
  File "/home/jobina/Documents/minproject/DRMS/DjangoV/lib/python3.10/site-packages/pymysql/connections.py", line 825, in _read_query_result
    result.read()
  File "/home/jobina/Documents/minproject/DRMS/DjangoV/lib/python3.10/site-packages/pymysql/connections.py", line 1199, in read
    first_packet = self.connection._read_packet()
  File "/home/jobina/Documents/minproject/DRMS/DjangoV/lib/python3.10/site-packages/pymysql/connections.py", line 775, in _read_packet
    packet.raise_for_error()
  File "/home/jobina/Documents/minproject/DRMS/DjangoV/lib/python3.10/site-packages/pymysql/protocol.py", line 219, in raise_for_error
    err.raise_mysql_exception(self._data)
  File "/home/jobina/Documents/minproject/DRMS/DjangoV/lib/python3.10/site-packages/pymysql/err.py", line 150, in raise_mysql_exception
    raise errorclass(errno, errval)
pymysql.err.OperationalError: (1054, "Unknown column 'updated_at' in 'field list'")

The above exception was the direct cause of the following exception:

Traceback (most recent call last):
  File "/home/jobina/Documents/minproject/DRMS/daycation/adminpanal/views.py", line 588, in process_booking
    booking = DaycationBooking.objects.create(
  File "/home/jobina/Documents/minproject/DRMS/DjangoV/lib/python3.10/site-packages/django/db/models/manager.py", line 87, in manager_method
    return getattr(self.get_queryset(), name)(*args, **kwargs)
  File "/home/jobina/Documents/minproject/DRMS/DjangoV/lib/python3.10/site-packages/django/db/models/query.py", line 679, in create
    obj.save(force_insert=True, using=self.db)
  File "/home/jobina/Documents/minproject/DRMS/daycation/adminpanal/models.py", line 257, in save
    super().save(*args, **kwargs)
  File "/home/jobina/Documents/minproject/DRMS/DjangoV/lib/python3.10/site-packages/django/db/models/base.py", line 891, in save
    self.save_base(
  File "/home/jobina/Documents/minproject/DRMS/DjangoV/lib/python3.10/site-packages/django/db/models/base.py", line 997, in save_base
    updated = self._save_table(
  File "/home/jobina/Documents/minproject/DRMS/DjangoV/lib/python3.10/site-packages/django/db/models/base.py", line 1160, in _save_table
    results = self._do_insert(
  File "/home/jobina/Documents/minproject/DRMS/DjangoV/lib/python3.10/site-packages/django/db/models/base.py", line 1201, in _do_insert
    return manager._insert(
  File "/home/jobina/Documents/minproject/DRMS/DjangoV/lib/python3.10/site-packages/django/db/models/manager.py", line 87, in manager_method
    return getattr(self.get_queryset(), name)(*args, **kwargs)
  File "/home/jobina/Documents/minproject/DRMS/DjangoV/lib/python3.10/site-packages/django/db/models/query.py", line 1847, in _insert
    return query.get_compiler(using=using).execute_sql(returning_fields)
  File "/home/jobina/Documents/minproject/DRMS/DjangoV/lib/python3.10/site-packages/django/db/models/sql/compiler.py", line 1836, in execute_sql
    cursor.execute(sql, params)
  File "/home/jobina/Documents/minproject/DRMS/DjangoV/lib/python3.10/site-packages/django/db/backends/utils.py", line 122, in execute
    return super().execute(sql, params)
  File "/home/jobina/Documents/minproject/DRMS/DjangoV/lib/python3.10/site-packages/django/db/backends/utils.py", line 79, in execute
    return self._execute_with_wrappers(
  File "/home/jobina/Documents/minproject/DRMS/DjangoV/lib/python3.10/site-packages/django/db/backends/utils.py", line 92, in _execute_with_wrappers
    return executor(sql, params, many, context)
  File "/home/jobina/Documents/minproject/DRMS/DjangoV/lib/python3.10/site-packages/django/db/backends/utils.py", line 100, in _execute
    with self.db.wrap_database_errors:
  File "/home/jobina/Documents/minproject/DRMS/DjangoV/lib/python3.10/site-packages/django/db/utils.py", line 91, in __exit__
    raise dj_exc_value.with_traceback(traceback) from exc_value
  File "/home/jobina/Documents/minproject/DRMS/DjangoV/lib/python3.10/site-packages/django/db/backends/utils.py", line 105, in _execute
    return self.cursor.execute(sql, params)
  File "/home/jobina/Documents/minproject/DRMS/DjangoV/lib/python3.10/site-packages/django/db/backends/mysql/base.py", line 76, in execute
    return self.cursor.execute(query, args)
  File "/home/jobina/Documents/minproject/DRMS/DjangoV/lib/python3.10/site-packages/pymysql/cursors.py", line 153, in execute
    result = self._query(query)
  File "/home/jobina/Documents/minproject/DRMS/DjangoV/lib/python3.10/site-packages/pymysql/cursors.py", line 322, in _query
    conn.query(q)
  File "/home/jobina/Documents/minproject/DRMS/DjangoV/lib/python3.10/site-packages/pymysql/connections.py", line 563, in query
    self._affected_rows = self._read_query_result(unbuffered=unbuffered)
  File "/home/jobina/Documents/minproject/DRMS/DjangoV/lib/python3.10/site-packages/pymysql/connections.py", line 825, in _read_query_result
    result.read()
  File "/home/jobina/Documents/minproject/DRMS/DjangoV/lib/python3.10/site-packages/pymysql/connections.py", line 1199, in read
    first_packet = self.connection._read_packet()
  File "/home/jobina/Documents/minproject/DRMS/DjangoV/lib/python3.10/site-packages/pymysql/connections.py", line 775, in _read_packet
    packet.raise_for_error()
  File "/home/jobina/Documents/minproject/DRMS/DjangoV/lib/python3.10/site-packages/pymysql/protocol.py", line 219, in raise_for_error
    err.raise_mysql_exception(self._data)
  File "/home/jobina/Documents/minproject/DRMS/DjangoV/lib/python3.10/site-packages/pymysql/err.py", line 150, in raise_mysql_exception
    raise errorclass(errno, errval)
django.db.utils.OperationalError: (1054, "Unknown column 'updated_at' in 'field list'")

Internal Server Error: /package/5/process_booking/
Watching for file changes with StatReloader
Session data corrupted
Processing booking for package 5
Session data corrupted
Starting new HTTPS connection (1): api.razorpay.com:443
https://api.razorpay.com:443 "POST /v1/orders HTTP/11" 200 215
Session data corrupted
Internal Server Error: /verify-payment/
Traceback (most recent call last):
  File "/home/jobina/Documents/minproject/DRMS/daycation/adminpanal/views.py", line 738, in verify_payment
    payment_data = json.loads(request.body)
NameError: name 'json' is not defined

During handling of the above exception, another exception occurred:

Traceback (most recent call last):
  File "/home/jobina/Documents/minproject/DRMS/DjangoV/lib/python3.10/site-packages/django/core/handlers/exception.py", line 55, in inner
    response = get_response(request)
  File "/home/jobina/Documents/minproject/DRMS/DjangoV/lib/python3.10/site-packages/django/core/handlers/base.py", line 197, in _get_response
    response = wrapped_callback(request, *callback_args, **callback_kwargs)
  File "/home/jobina/Documents/minproject/DRMS/DjangoV/lib/python3.10/site-packages/django/views/decorators/http.py", line 64, in inner
    return func(request, *args, **kwargs)
  File "/home/jobina/Documents/minproject/DRMS/daycation/adminpanal/views.py", line 756, in verify_payment
    except json.JSONDecodeError as e:
NameError: name 'json' is not defined
/home/jobina/Documents/minproject/DRMS/daycation/adminpanal/views.py changed, reloading.
Watching for file changes with StatReloader
Session data corrupted
Processing booking for package 5
Session data corrupted
Starting new HTTPS connection (1): api.razorpay.com:443
https://api.razorpay.com:443 "POST /v1/orders HTTP/11" 200 215
Session data corrupted
Internal Server Error: /verify-payment/
Traceback (most recent call last):
  File "/home/jobina/Documents/minproject/DRMS/daycation/adminpanal/views.py", line 736, in verify_payment
    payment_data = json.loads(request.body)
NameError: name 'json' is not defined

During handling of the above exception, another exception occurred:

Traceback (most recent call last):
  File "/home/jobina/Documents/minproject/DRMS/DjangoV/lib/python3.10/site-packages/django/core/handlers/exception.py", line 55, in inner
    response = get_response(request)
  File "/home/jobina/Documents/minproject/DRMS/DjangoV/lib/python3.10/site-packages/django/core/handlers/base.py", line 197, in _get_response
    response = wrapped_callback(request, *callback_args, **callback_kwargs)
  File "/home/jobina/Documents/minproject/DRMS/DjangoV/lib/python3.10/site-packages/django/views/decorators/http.py", line 64, in inner
    return func(request, *args, **kwargs)
  File "/home/jobina/Documents/minproject/DRMS/daycation/adminpanal/views.py", line 759, in verify_payment
    except json.JSONDecodeError as e:
NameError: name 'json' is not defined
/home/jobina/Documents/minproject/DRMS/daycation/adminpanal/views.py changed, reloading.
Watching for file changes with StatReloader
Session data corrupted
Processing booking for package 5
Session data corrupted
Starting new HTTPS connection (1): api.razorpay.com:443
https://api.razorpay.com:443 "POST /v1/orders HTTP/11" 200 215
/home/jobina/Documents/minproject/DRMS/daycation/adminpanal/views.py changed, reloading.
Watching for file changes with StatReloader
/home/jobina/Documents/minproject/DRMS/daycation/daycation/settings.py changed, reloading.
Watching for file changes with StatReloader
/home/jobina/Documents/minproject/DRMS/daycation/adminpanal/views.py changed, reloading.
Watching for file changes with StatReloader
/home/jobina/Documents/minproject/DRMS/daycation/adminpanal/views.py changed, reloading.
Watching for file changes with StatReloader
Watching for file changes with StatReloader
Session data corrupted
Processing booking for package 5
Session data corrupted
Starting new HTTPS connection (1): api.razorpay.com:443
https://api.razorpay.com:443 "POST /v1/orders HTTP/11" 200 213
Session data corrupted
Internal Server Error: /verify-payment/
Traceback (most recent call last):
  File "/home/jobina/Documents/minproject/DRMS/daycation/adminpanal/views.py", line 735, in verify_payment
    payment_data = json.loads(request.body)
NameError: name 'json' is not defined

During handling of the above exception, another exception occurred:

Traceback (most recent call last):
  File "/home/jobina/Documents/minproject/DRMS/DjangoV/lib/python3.10/site-packages/django/core/handlers/exception.py", line 55, in inner
    response = get_response(request)
  File "/home/jobina/Documents/minproject/DRMS/DjangoV/lib/python3.10/site-packages/django/core/handlers/base.py", line 197, in _get_response
    response = wrapped_callback(request, *callback_args, **callback_kwargs)
  File "/home/jobina/Documents/minproject/DRMS/DjangoV/lib/python3.10/site-packages/django/views/decorators/http.py", line 64, in inner
    return func(request, *args, **kwargs)
  File "/home/jobina/Documents/minproject/DRMS/daycation/adminpanal/views.py", line 758, in verify_payment
    except json.JSONDecodeError as e:
NameError: name 'json' is not defined
Processing booking for package 5
Session data corrupted
https://api.razorpay.com:443 "POST /v1/orders HTTP/11" 200 213
Session data corrupted
Internal Server Error: /verify-payment/
Traceback (most recent call last):
  File "/home/jobina/Documents/minproject/DRMS/daycation/adminpanal/views.py", line 735, in verify_payment
    payment_data = json.loads(request.body)
NameError: name 'json' is not defined

During handling of the above exception, another exception occurred:

Traceback (most recent call last):
  File "/home/jobina/Documents/minproject/DRMS/DjangoV/lib/python3.10/site-packages/django/core/handlers/exception.py", line 55, in inner
    response = get_response(request)
  File "/home/jobina/Documents/minproject/DRMS/DjangoV/lib/python3.10/site-packages/django/core/handlers/base.py", line 197, in _get_response
    response = wrapped_callback(request, *callback_args, **callback_kwargs)
  File "/home/jobina/Documents/minproject/DRMS/DjangoV/lib/python3.10/site-packages/django/views/decorators/http.py", line 64, in inner
    return func(request, *args, **kwargs)
  File "/home/jobina/Documents/minproject/DRMS/daycation/adminpanal/views.py", line 758, in verify_payment
    except json.JSONDecodeError as e:
NameError: name 'json' is not defined
Processing booking for package 5
Session data corrupted
https://api.razorpay.com:443 "POST /v1/orders HTTP/11" 200 213
Session data corrupted
Processing booking for package 5
Session data corrupted
https://api.razorpay.com:443 "POST /v1/orders HTTP/11" 200 213
/home/jobina/Documents/minproject/DRMS/daycation/adminpanal/views.py changed, reloading.
Watching for file changes with StatReloader
/home/jobina/Documents/minproject/DRMS/daycation/adminpanal/views.py changed, reloading.
Watching for file changes with StatReloader
Session data corrupted
Processing booking for package 5
Session data corrupted
Starting new HTTPS connection (1): api.razorpay.com:443
https://api.razorpay.com:443 "POST /v1/orders HTTP/11" 200 215
Session data corrupted
Internal Server Error: /verify-payment/
Traceback (most recent call last):
  File "/home/jobina/Documents/minproject/DRMS/daycation/adminpanal/views.py", line 735, in verify_payment
    payment_data = json.loads(request.body)
NameError: name 'json' is not defined

During handling of the above exception, another exception occurred:

Traceback (most recent call last):
  File "/home/jobina/Documents/minproject/DRMS/DjangoV/lib/python3.10/site-packages/django/core/handlers/exception.py", line 55, in inner
    response = get_response(request)
  File "/home/jobina/Documents/minproject/DRMS/DjangoV/lib/python3.10/site-packages/django/core/handlers/base.py", line 197, in _get_response
    response = wrapped_callback(request, *callback_args, **callback_kwargs)
  File "/home/jobina/Documents/minproject/DRMS/DjangoV/lib/python3.10/site-packages/django/views/decorators/http.py", line 64, in inner
    return func(request, *args, **kwargs)
  File "/home/jobina/Documents/minproject/DRMS/daycation/adminpanal/views.py", line 758, in verify_payment
    except json.JSONDecodeError as e:
NameError: name 'json' is not defined
Processing booking for package 5
Session data corrupted
Processing booking for package 5
Session data corrupted
Starting new HTTPS connection (2): api.razorpay.com:443
https://api.razorpay.com:443 "POST /v1/orders HTTP/11" 200 215
Session data corrupted
Session data corrupted
/home/jobina/Documents/minproject/DRMS/daycation/adminpanal/views.py changed, reloading.
Watching for file changes with StatReloader
/home/jobina/Documents/minproject/DRMS/daycation/adminpanal/urls.py changed, reloading.
Watching for file changes with StatReloader
/home/jobina/Documents/minproject/DRMS/daycation/adminpanal/urls.py changed, reloading.
Watching for file changes with StatReloader
Session data corrupted
Session data corrupted
Internal Server Error: /create-razorpay-order/
Traceback (most recent call last):
  File "/home/jobina/Documents/minproject/DRMS/DjangoV/lib/python3.10/site-packages/django/core/handlers/exception.py", line 55, in inner
    response = get_response(request)
  File "/home/jobina/Documents/minproject/DRMS/DjangoV/lib/python3.10/site-packages/django/core/handlers/base.py", line 197, in _get_response
    response = wrapped_callback(request, *callback_args, **callback_kwargs)
  File "/home/jobina/Documents/minproject/DRMS/DjangoV/lib/python3.10/site-packages/django/views/decorators/csrf.py", line 65, in _view_wrapper
    return view_func(request, *args, **kwargs)
  File "/home/jobina/Documents/minproject/DRMS/daycation/adminpanal/views.py", line 771, in create_razorpay_order
    amount = json.loads(request.body).get('amount')
NameError: name 'json' is not defined
/home/jobina/Documents/minproject/DRMS/daycation/adminpanal/views.py changed, reloading.
Watching for file changes with StatReloader
Session data corrupted
Session data corrupted
Internal Server Error: /create-razorpay-order/
Traceback (most recent call last):
  File "/home/jobina/Documents/minproject/DRMS/DjangoV/lib/python3.10/site-packages/django/core/handlers/exception.py", line 55, in inner
    response = get_response(request)
  File "/home/jobina/Documents/minproject/DRMS/DjangoV/lib/python3.10/site-packages/django/core/handlers/base.py", line 197, in _get_response
    response = wrapped_callback(request, *callback_args, **callback_kwargs)
  File "/home/jobina/Documents/minproject/DRMS/DjangoV/lib/python3.10/site-packages/django/views/decorators/csrf.py", line 65, in _view_wrapper
    return view_func(request, *args, **kwargs)
  File "/home/jobina/Documents/minproject/DRMS/daycation/adminpanal/views.py", line 773, in create_razorpay_order
    amount = json.loads(request.body).get('amount')
NameError: name 'json' is not defined
/home/jobina/Documents/minproject/DRMS/daycation/adminpanal/views.py changed, reloading.
Watching for file changes with StatReloader
/home/jobina/Documents/minproject/DRMS/daycation/adminpanal/views.py changed, reloading.
Watching for file changes with StatReloader
Session data corrupted
Session data corrupted
Internal Server Error: /create-razorpay-order/
Traceback (most recent call last):
  File "/home/jobina/Documents/minproject/DRMS/DjangoV/lib/python3.10/site-packages/django/core/handlers/exception.py", line 55, in inner
    response = get_response(request)
  File "/home/jobina/Documents/minproject/DRMS/DjangoV/lib/python3.10/site-packages/django/core/handlers/base.py", line 197, in _get_response
    response = wrapped_callback(request, *callback_args, **callback_kwargs)
  File "/home/jobina/Documents/minproject/DRMS/DjangoV/lib/python3.10/site-packages/django/views/decorators/csrf.py", line 65, in _view_wrapper
    return view_func(request, *args, **kwargs)
  File "/home/jobina/Documents/minproject/DRMS/daycation/adminpanal/views.py", line 741, in create_razorpay_order
    amount = json.loads(request.body).get('amount')
NameError: name 'json' is not defined
/home/jobina/Documents/minproject/DRMS/daycation/adminpanal/views.py changed, reloading.
Watching for file changes with StatReloader
/home/jobina/Documents/minproject/DRMS/daycation/adminpanal/urls.py changed, reloading.
Watching for file changes with StatReloader
Watching for file changes with StatReloader
/home/jobina/Documents/minproject/DRMS/daycation/adminpanal/views.py changed, reloading.
Watching for file changes with StatReloader
/home/jobina/Documents/minproject/DRMS/daycation/adminpanal/views.py changed, reloading.
Watching for file changes with StatReloader
Session data corrupted
Bad Request: /create-razorpay-order/
/home/jobina/Documents/minproject/DRMS/daycation/adminpanal/views.py changed, reloading.
Watching for file changes with StatReloader
/home/jobina/Documents/minproject/DRMS/daycation/adminpanal/views.py changed, reloading.
Watching for file changes with StatReloader
/home/jobina/Documents/minproject/DRMS/daycation/adminpanal/views.py changed, reloading.
Watching for file changes with StatReloader
/home/jobina/Documents/minproject/DRMS/daycation/adminpanal/urls.py changed, reloading.
Watching for file changes with StatReloader
Session data corrupted
Processing booking for package 5
Session data corrupted
Starting new HTTPS connection (1): api.razorpay.com:443
https://api.razorpay.com:443 "POST /v1/orders HTTP/11" 200 215
Session data corrupted
Internal Server Error: /verify-payment/
Traceback (most recent call last):
  File "/home/jobina/Documents/minproject/DRMS/DjangoV/lib/python3.10/site-packages/django/core/handlers/exception.py", line 55, in inner
    response = get_response(request)
  File "/home/jobina/Documents/minproject/DRMS/DjangoV/lib/python3.10/site-packages/django/core/handlers/base.py", line 197, in _get_response
    response = wrapped_callback(request, *callback_args, **callback_kwargs)
  File "/home/jobina/Documents/minproject/DRMS/DjangoV/lib/python3.10/site-packages/django/views/decorators/http.py", line 64, in inner
    return func(request, *args, **kwargs)
  File "/home/jobina/Documents/minproject/DRMS/daycation/adminpanal/views.py", line 737, in verify_payment
    payment_data = json.loads(request.body)
NameError: name 'json' is not defined
/home/jobina/Documents/minproject/DRMS/daycation/adminpanal/views.py changed, reloading.
Watching for file changes with StatReloader
/home/jobina/Documents/minproject/DRMS/daycation/adminpanal/views.py changed, reloading.
Watching for file changes with StatReloader
/home/jobina/Documents/minproject/DRMS/daycation/adminpanal/views.py changed, reloading.
Watching for file changes with StatReloader
Session data corrupted
Session data corrupted
Bad Request: /package/5/process_booking/
Session data corrupted
Bad Request: /package/5/process_booking/
Session data corrupted
Bad Request: /package/5/process_booking/
Session data corrupted
Bad Request: /package/5/process_booking/
/home/jobina/Documents/minproject/DRMS/daycation/adminpanal/views.py changed, reloading.
Watching for file changes with StatReloader
/home/jobina/Documents/minproject/DRMS/daycation/adminpanal/views.py changed, reloading.
Watching for file changes with StatReloader
Session data corrupted
Bad Request: /package/5/process_booking/
/home/jobina/Documents/minproject/DRMS/daycation/adminpanal/views.py changed, reloading.
Watching for file changes with StatReloader
Session data corrupted
Processing booking for package 5
Session data corrupted
Starting new HTTPS connection (1): api.razorpay.com:443
https://api.razorpay.com:443 "POST /v1/orders HTTP/11" 200 215
Session data corrupted
Internal Server Error: /verify-payment/
Traceback (most recent call last):
  File "/home/jobina/Documents/minproject/DRMS/DjangoV/lib/python3.10/site-packages/django/core/handlers/exception.py", line 55, in inner
    response = get_response(request)
  File "/home/jobina/Documents/minproject/DRMS/DjangoV/lib/python3.10/site-packages/django/core/handlers/base.py", line 197, in _get_response
    response = wrapped_callback(request, *callback_args, **callback_kwargs)
  File "/home/jobina/Documents/minproject/DRMS/DjangoV/lib/python3.10/site-packages/django/views/decorators/http.py", line 64, in inner
    return func(request, *args, **kwargs)
  File "/home/jobina/Documents/minproject/DRMS/daycation/adminpanal/views.py", line 737, in verify_payment
    payment_data = json.loads(request.body)
NameError: name 'json' is not defined
Session data corrupted
Session data corrupted
Internal Server Error: /package/5/book/
Traceback (most recent call last):
  File "/home/jobina/Documents/minproject/DRMS/DjangoV/lib/python3.10/site-packages/django/core/handlers/exception.py", line 55, in inner
    response = get_response(request)
  File "/home/jobina/Documents/minproject/DRMS/DjangoV/lib/python3.10/site-packages/django/core/handlers/base.py", line 197, in _get_response
    response = wrapped_callback(request, *callback_args, **callback_kwargs)
  File "/home/jobina/Documents/minproject/DRMS/daycation/adminpanal/views.py", line 558, in book_package
    return render(request, 'book_package.html', context)
  File "/home/jobina/Documents/minproject/DRMS/DjangoV/lib/python3.10/site-packages/django/shortcuts.py", line 25, in render
    content = loader.render_to_string(template_name, context, request, using=using)
  File "/home/jobina/Documents/minproject/DRMS/DjangoV/lib/python3.10/site-packages/django/template/loader.py", line 62, in render_to_string
    return template.render(context, request)
  File "/home/jobina/Documents/minproject/DRMS/DjangoV/lib/python3.10/site-packages/django/template/backends/django.py", line 107, in render
    return self.template.render(context)
  File "/home/jobina/Documents/minproject/DRMS/DjangoV/lib/python3.10/site-packages/django/template/base.py", line 171, in render
    return self._render(context)
  File "/home/jobina/Documents/minproject/DRMS/DjangoV/lib/python3.10/site-packages/django/template/base.py", line 163, in _render
    return self.nodelist.render(context)
  File "/home/jobina/Documents/minproject/DRMS/DjangoV/lib/python3.10/site-packages/django/template/base.py", line 1008, in render
    return SafeString("".join([node.render_annotated(context) for node in self]))
  File "/home/jobina/Documents/minproject/DRMS/DjangoV/lib/python3.10/site-packages/django/template/base.py", line 1008, in <listcomp>
    return SafeString("".join([node.render_annotated(context) for node in self]))
  File "/home/jobina/Documents/minproject/DRMS/DjangoV/lib/python3.10/site-packages/django/template/base.py", line 969, in render_annotated
    return self.render(context)
  File "/home/jobina/Documents/minproject/DRMS/DjangoV/lib/python3.10/site-packages/django/template/loader_tags.py", line 159, in render
    return compiled_parent._render(context)
  File "/home/jobina/Documents/minproject/DRMS/DjangoV/lib/python3.10/site-packages/django/template/base.py", line 163, in _render
    return self.nodelist.render(context)
  File "/home/jobina/Documents/minproject/DRMS/DjangoV/lib/python3.10/site-packages/django/template/base.py", line 1008, in render
    return SafeString("".join([node.render_annotated(context) for node in self]))
  File "/home/jobina/Documents/minproject/DRMS/DjangoV/lib/python3.10/site-packages/django/template/base.py", line 1008, in <listcomp>
    return SafeString("".join([node.render_annotated(context) for node in self]))
  File "/home/jobina/Documents/minproject/DRMS/DjangoV/lib/python3.10/site-packages/django/template/base.py", line 969, in render_annotated
    return self.render(context)
  File "/home/jobina/Documents/minproject/DRMS/DjangoV/lib/python3.10/site-packages/django/template/loader_tags.py", line 65, in render
    result = block.nodelist.render(context)
  File "/home/jobina/Documents/minproject/DRMS/DjangoV/lib/python3.10/site-packages/django/template/base.py", line 1008, in render
    return SafeString("".join([node.render_annotated(context) for node in self]))
  File "/home/jobina/Documents/minproject/DRMS/DjangoV/lib/python3.10/site-packages/django/template/base.py", line 1008, in <listcomp>
    return SafeString("".join([node.render_annotated(context) for node in self]))
  File "/home/jobina/Documents/minproject/DRMS/DjangoV/lib/python3.10/site-packages/django/template/base.py", line 969, in render_annotated
    return self.render(context)
  File "/home/jobina/Documents/minproject/DRMS/DjangoV/lib/python3.10/site-packages/django/template/defaulttags.py", line 480, in render
    url = reverse(view_name, args=args, kwargs=kwargs, current_app=current_app)
  File "/home/jobina/Documents/minproject/DRMS/DjangoV/lib/python3.10/site-packages/django/urls/base.py", line 88, in reverse
    return resolver._reverse_with_prefix(view, prefix, *args, **kwargs)
  File "/home/jobina/Documents/minproject/DRMS/DjangoV/lib/python3.10/site-packages/django/urls/resolvers.py", line 831, in _reverse_with_prefix
    raise NoReverseMatch(msg)
django.urls.exceptions.NoReverseMatch: Reverse for 'package_detail' not found. 'package_detail' is not a valid view function or pattern name.
Session data corrupted
Session data corrupted
Session data corrupted
Processing booking for package 5
Session data corrupted
Error processing booking: ('Connection aborted.', RemoteDisconnected('Remote end closed connection without response'))
Traceback (most recent call last):
  File "/home/jobina/Documents/minproject/DRMS/DjangoV/lib/python3.10/site-packages/urllib3/connectionpool.py", line 789, in urlopen
    response = self._make_request(
  File "/home/jobina/Documents/minproject/DRMS/DjangoV/lib/python3.10/site-packages/urllib3/connectionpool.py", line 536, in _make_request
    response = conn.getresponse()
  File "/home/jobina/Documents/minproject/DRMS/DjangoV/lib/python3.10/site-packages/urllib3/connection.py", line 464, in getresponse
    httplib_response = super().getresponse()
  File "/usr/lib/python3.10/http/client.py", line 1375, in getresponse
    response.begin()
  File "/usr/lib/python3.10/http/client.py", line 318, in begin
    version, status, reason = self._read_status()
  File "/usr/lib/python3.10/http/client.py", line 287, in _read_status
    raise RemoteDisconnected("Remote end closed connection without"
http.client.RemoteDisconnected: Remote end closed connection without response

During handling of the above exception, another exception occurred:

Traceback (most recent call last):
  File "/home/jobina/Documents/minproject/DRMS/DjangoV/lib/python3.10/site-packages/requests/adapters.py", line 667, in send
    resp = conn.urlopen(
  File "/home/jobina/Documents/minproject/DRMS/DjangoV/lib/python3.10/site-packages/urllib3/connectionpool.py", line 843, in urlopen
    retries = retries.increment(
  File "/home/jobina/Documents/minproject/DRMS/DjangoV/lib/python3.10/site-packages/urllib3/util/retry.py", line 474, in increment
    raise reraise(type(error), error, _stacktrace)
  File "/home/jobina/Documents/minproject/DRMS/DjangoV/lib/python3.10/site-packages/urllib3/util/util.py", line 38, in reraise
    raise value.with_traceback(tb)
  File "/home/jobina/Documents/minproject/DRMS/DjangoV/lib/python3.10/site-packages/urllib3/connectionpool.py", line 789, in urlopen
    response = self._make_request(
  File "/home/jobina/Documents/minproject/DRMS/DjangoV/lib/python3.10/site-packages/urllib3/connectionpool.py", line 536, in _make_request
    response = conn.getresponse()
  File "/home/jobina/Documents/minproject/DRMS/DjangoV/lib/python3.10/site-packages/urllib3/connection.py", line 464, in getresponse
    httplib_response = super().getresponse()
  File "/usr/lib/python3.10/http/client.py", line 1375, in getresponse
    response.begin()
  File "/usr/lib/python3.10/http/client.py", line 318, in begin
    version, status, reason = self._read_status()
  File "/usr/lib/python3.10/http/client.py", line 287, in _read_status
    raise RemoteDisconnected("Remote end closed connection without"
urllib3.exceptions.ProtocolError: ('Connection aborted.', RemoteDisconnected('Remote end closed connection without response'))

During handling of the above exception, another exception occurred:

Traceback (most recent call last):
  File "/home/jobina/Documents/minproject/DRMS/daycation/adminpanal/views.py", line 606, in process_booking
    razorpay_order = client.order.create({
  File "/home/jobina/Documents/minproject/DRMS/DjangoV/lib/python3.10/site-packages/razorpay/resources/order.py", line 71, in create
    return self.post_url(url, data, **kwargs)
  File "/home/jobina/Documents/minproject/DRMS/DjangoV/lib/python3.10/site-packages/razorpay/resources/base.py", line 20, in post_url
    return self.client.post(url, data, **kwargs)
  File "/home/jobina/Documents/minproject/DRMS/DjangoV/lib/python3.10/site-packages/razorpay/client.py", line 156, in post
    return self.request('post', path, data=data, **options)
  File "/home/jobina/Documents/minproject/DRMS/DjangoV/lib/python3.10/site-packages/razorpay/client.py", line 120, in request
    response = getattr(self.session, method)(url, auth=self.auth,
  File "/home/jobina/Documents/minproject/DRMS/DjangoV/lib/python3.10/site-packages/requests/sessions.py", line 637, in post
    return self.request("POST", url, data=data, json=json, **kwargs)
  File "/home/jobina/Documents/minproject/DRMS/DjangoV/lib/python3.10/site-packages/requests/sessions.py", line 589, in request
    resp = self.send(prep, **send_kwargs)
  File "/home/jobina/Documents/minproject/DRMS/DjangoV/lib/python3.10/site-packages/requests/sessions.py", line 703, in send
    r = adapter.send(request, **kwargs)
  File "/home/jobina/Documents/minproject/DRMS/DjangoV/lib/python3.10/site-packages/requests/adapters.py", line 682, in send
    raise ConnectionError(err, request=request)
requests.exceptions.ConnectionError: ('Connection aborted.', RemoteDisconnected('Remote end closed connection without response'))

Internal Server Error: /package/5/process_booking/
Session data corrupted
Session data corrupted
Session data corrupted
Processing booking for package 5
Session data corrupted
Starting new HTTPS connection (2): api.razorpay.com:443
https://api.razorpay.com:443 "POST /v1/orders HTTP/11" 200 215
Session data corrupted
Internal Server Error: /verify-payment/
Traceback (most recent call last):
  File "/home/jobina/Documents/minproject/DRMS/DjangoV/lib/python3.10/site-packages/django/core/handlers/exception.py", line 55, in inner
    response = get_response(request)
  File "/home/jobina/Documents/minproject/DRMS/DjangoV/lib/python3.10/site-packages/django/core/handlers/base.py", line 197, in _get_response
    response = wrapped_callback(request, *callback_args, **callback_kwargs)
  File "/home/jobina/Documents/minproject/DRMS/DjangoV/lib/python3.10/site-packages/django/views/decorators/http.py", line 64, in inner
    return func(request, *args, **kwargs)
  File "/home/jobina/Documents/minproject/DRMS/daycation/adminpanal/views.py", line 737, in verify_payment
    payment_data = json.loads(request.body)
NameError: name 'json' is not defined
Watching for file changes with StatReloader
Not Found: /favicon.ico
Watching for file changes with StatReloader
Not Found: /favicon.ico
Session data corrupted
Session data corrupted
Session data corrupted
Session data corrupted
Session data corrupted
Session data corrupted
Session data corrupted
Session data corrupted
Session data corrupted
Session data corrupted
Processing booking for package 5
Starting new HTTPS connection (1): api.razorpay.com:443
Error processing booking: HTTPSConnectionPool(host='api.razorpay.com', port=443): Max retries exceeded with url: /v1/orders (Caused by SSLError(SSLCertVerificationError(1, '[SSL: CERTIFICATE_VERIFY_FAILED] certificate verify failed: self-signed certificate in certificate chain (_ssl.c:1007)')))
Traceback (most recent call last):
  File "/home/jobina/Documents/minproject/DRMS/DjangoV/lib/python3.10/site-packages/urllib3/connectionpool.py", line 466, in _make_request
    self._validate_conn(conn)
  File "/home/jobina/Documents/minproject/DRMS/DjangoV/lib/python3.10/site-packages/urllib3/connectionpool.py", line 1095, in _validate_conn
    conn.connect()
  File "/home/jobina/Documents/minproject/DRMS/DjangoV/lib/python3.10/site-packages/urllib3/connection.py", line 652, in connect
    sock_and_verified = _ssl_wrap_socket_and_match_hostname(
  File "/home/jobina/Documents/minproject/DRMS/DjangoV/lib/python3.10/site-packages/urllib3/connection.py", line 805, in _ssl_wrap_socket_and_match_hostname
    ssl_sock = ssl_wrap_socket(
  File "/home/jobina/Documents/minproject/DRMS/DjangoV/lib/python3.10/site-packages/urllib3/util/ssl_.py", line 465, in ssl_wrap_socket
    ssl_sock = _ssl_wrap_socket_impl(sock, context, tls_in_tls, server_hostname)
  File "/home/jobina/Documents/minproject/DRMS/DjangoV/lib/python3.10/site-packages/urllib3/util/ssl_.py", line 509, in _ssl_wrap_socket_impl
    return ssl_context.wrap_socket(sock, server_hostname=server_hostname)
  File "/usr/lib/python3.10/ssl.py", line 513, in wrap_socket
    return self.sslsocket_class._create(
  File "/usr/lib/python3.10/ssl.py", line 1100, in _create
    self.do_handshake()
  File "/usr/lib/python3.10/ssl.py", line 1371, in do_handshake
    self._sslobj.do_handshake()
ssl.SSLCertVerificationError: [SSL: CERTIFICATE_VERIFY_FAILED] certificate verify failed: self-signed certificate in certificate chain (_ssl.c:1007)

During handling of the above exception, another exception occurred:

Traceback (most recent call last):
  File "/home/jobina/Documents/minproject/DRMS/DjangoV/lib/python3.10/site-packages/urllib3/connectionpool.py", line 789, in urlopen
    response = self._make_request(
  File "/home/jobina/Documents/minproject/DRMS/DjangoV/lib/python3.10/site-packages/urllib3/connectionpool.py", line 490, in _make_request
    raise new_e
urllib3.exceptions.SSLError: [SSL: CERTIFICATE_VERIFY_FAILED] certificate verify failed: self-signed certificate in certificate chain (_ssl.c:1007)

The above exception was the direct cause of the following exception:

Traceback (most recent call last):
  File "/home/jobina/Documents/minproject/DRMS/DjangoV/lib/python3.10/site-packages/requests/adapters.py", line 667, in send
    resp = conn.urlopen(
  File "/home/jobina/Documents/minproject/DRMS/DjangoV/lib/python3.10/site-packages/urllib3/connectionpool.py", line 843, in urlopen
    retries = retries.increment(
  File "/home/jobina/Documents/minproject/DRMS/DjangoV/lib/python3.10/site-packages/urllib3/util/retry.py", line 519, in increment
    raise MaxRetryError(_pool, url, reason) from reason  # type: ignore[arg-type]
urllib3.exceptions.MaxRetryError: HTTPSConnectionPool(host='api.razorpay.com', port=443): Max retries exceeded with url: /v1/orders (Caused by SSLError(SSLCertVerificationError(1, '[SSL: CERTIFICATE_VERIFY_FAILED] certificate verify failed: self-signed certificate in certificate chain (_ssl.c:1007)')))

During handling of the above exception, another exception occurred:

Traceback (most recent call last):
  File "/home/jobina/Documents/minproject/DRMS/daycation/adminpanal/views.py", line 606, in process_booking
    razorpay_order = client.order.create({
  File "/home/jobina/Documents/minproject/DRMS/DjangoV/lib/python3.10/site-packages/razorpay/resources/order.py", line 71, in create
    return self.post_url(url, data, **kwargs)
  File "/home/jobina/Documents/minproject/DRMS/DjangoV/lib/python3.10/site-packages/razorpay/resources/base.py", line 20, in post_url
    return self.client.post(url, data, **kwargs)
  File "/home/jobina/Documents/minproject/DRMS/DjangoV/lib/python3.10/site-packages/razorpay/client.py", line 156, in post
    return self.request('post', path, data=data, **options)
  File "/home/jobina/Documents/minproject/DRMS/DjangoV/lib/python3.10/site-packages/razorpay/client.py", line 120, in request
    response = getattr(self.session, method)(url, auth=self.auth,
  File "/home/jobina/Documents/minproject/DRMS/DjangoV/lib/python3.10/site-packages/requests/sessions.py", line 637, in post
    return self.request("POST", url, data=data, json=json, **kwargs)
  File "/home/jobina/Documents/minproject/DRMS/DjangoV/lib/python3.10/site-packages/requests/sessions.py", line 589, in request
    resp = self.send(prep, **send_kwargs)
  File "/home/jobina/Documents/minproject/DRMS/DjangoV/lib/python3.10/site-packages/requests/sessions.py", line 703, in send
    r = adapter.send(request, **kwargs)
  File "/home/jobina/Documents/minproject/DRMS/DjangoV/lib/python3.10/site-packages/requests/adapters.py", line 698, in send
    raise SSLError(e, request=request)
requests.exceptions.SSLError: HTTPSConnectionPool(host='api.razorpay.com', port=443): Max retries exceeded with url: /v1/orders (Caused by SSLError(SSLCertVerificationError(1, '[SSL: CERTIFICATE_VERIFY_FAILED] certificate verify failed: self-signed certificate in certificate chain (_ssl.c:1007)')))

Internal Server Error: /package/5/process_booking/
Processing booking for package 5
Starting new HTTPS connection (2): api.razorpay.com:443
Error processing booking: HTTPSConnectionPool(host='api.razorpay.com', port=443): Max retries exceeded with url: /v1/orders (Caused by SSLError(SSLCertVerificationError(1, '[SSL: CERTIFICATE_VERIFY_FAILED] certificate verify failed: self-signed certificate in certificate chain (_ssl.c:1007)')))
Traceback (most recent call last):
  File "/home/jobina/Documents/minproject/DRMS/DjangoV/lib/python3.10/site-packages/urllib3/connectionpool.py", line 466, in _make_request
    self._validate_conn(conn)
  File "/home/jobina/Documents/minproject/DRMS/DjangoV/lib/python3.10/site-packages/urllib3/connectionpool.py", line 1095, in _validate_conn
    conn.connect()
  File "/home/jobina/Documents/minproject/DRMS/DjangoV/lib/python3.10/site-packages/urllib3/connection.py", line 652, in connect
    sock_and_verified = _ssl_wrap_socket_and_match_hostname(
  File "/home/jobina/Documents/minproject/DRMS/DjangoV/lib/python3.10/site-packages/urllib3/connection.py", line 805, in _ssl_wrap_socket_and_match_hostname
    ssl_sock = ssl_wrap_socket(
  File "/home/jobina/Documents/minproject/DRMS/DjangoV/lib/python3.10/site-packages/urllib3/util/ssl_.py", line 465, in ssl_wrap_socket
    ssl_sock = _ssl_wrap_socket_impl(sock, context, tls_in_tls, server_hostname)
  File "/home/jobina/Documents/minproject/DRMS/DjangoV/lib/python3.10/site-packages/urllib3/util/ssl_.py", line 509, in _ssl_wrap_socket_impl
    return ssl_context.wrap_socket(sock, server_hostname=server_hostname)
  File "/usr/lib/python3.10/ssl.py", line 513, in wrap_socket
    return self.sslsocket_class._create(
  File "/usr/lib/python3.10/ssl.py", line 1100, in _create
    self.do_handshake()
  File "/usr/lib/python3.10/ssl.py", line 1371, in do_handshake
    self._sslobj.do_handshake()
ssl.SSLCertVerificationError: [SSL: CERTIFICATE_VERIFY_FAILED] certificate verify failed: self-signed certificate in certificate chain (_ssl.c:1007)

During handling of the above exception, another exception occurred:

Traceback (most recent call last):
  File "/home/jobina/Documents/minproject/DRMS/DjangoV/lib/python3.10/site-packages/urllib3/connectionpool.py", line 789, in urlopen
    response = self._make_request(
  File "/home/jobina/Documents/minproject/DRMS/DjangoV/lib/python3.10/site-packages/urllib3/connectionpool.py", line 490, in _make_request
    raise new_e
urllib3.exceptions.SSLError: [SSL: CERTIFICATE_VERIFY_FAILED] certificate verify failed: self-signed certificate in certificate chain (_ssl.c:1007)

The above exception was the direct cause of the following exception:

Traceback (most recent call last):
  File "/home/jobina/Documents/minproject/DRMS/DjangoV/lib/python3.10/site-packages/requests/adapters.py", line 667, in send
    resp = conn.urlopen(
  File "/home/jobina/Documents/minproject/DRMS/DjangoV/lib/python3.10/site-packages/urllib3/connectionpool.py", line 843, in urlopen
    retries = retries.increment(
  File "/home/jobina/Documents/minproject/DRMS/DjangoV/lib/python3.10/site-packages/urllib3/util/retry.py", line 519, in increment
    raise MaxRetryError(_pool, url, reason) from reason  # type: ignore[arg-type]
urllib3.exceptions.MaxRetryError: HTTPSConnectionPool(host='api.razorpay.com', port=443): Max retries exceeded with url: /v1/orders (Caused by SSLError(SSLCertVerificationError(1, '[SSL: CERTIFICATE_VERIFY_FAILED] certificate verify failed: self-signed certificate in certificate chain (_ssl.c:1007)')))

During handling of the above exception, another exception occurred:

Traceback (most recent call last):
  File "/home/jobina/Documents/minproject/DRMS/daycation/adminpanal/views.py", line 606, in process_booking
    razorpay_order = client.order.create({
  File "/home/jobina/Documents/minproject/DRMS/DjangoV/lib/python3.10/site-packages/razorpay/resources/order.py", line 71, in create
    return self.post_url(url, data, **kwargs)
  File "/home/jobina/Documents/minproject/DRMS/DjangoV/lib/python3.10/site-packages/razorpay/resources/base.py", line 20, in post_url
    return self.client.post(url, data, **kwargs)
  File "/home/jobina/Documents/minproject/DRMS/DjangoV/lib/python3.10/site-packages/razorpay/client.py", line 156, in post
    return self.request('post', path, data=data, **options)
  File "/home/jobina/Documents/minproject/DRMS/DjangoV/lib/python3.10/site-packages/razorpay/client.py", line 120, in request
    response = getattr(self.session, method)(url, auth=self.auth,
  File "/home/jobina/Documents/minproject/DRMS/DjangoV/lib/python3.10/site-packages/requests/sessions.py", line 637, in post
    return self.request("POST", url, data=data, json=json, **kwargs)
  File "/home/jobina/Documents/minproject/DRMS/DjangoV/lib/python3.10/site-packages/requests/sessions.py", line 589, in request
    resp = self.send(prep, **send_kwargs)
  File "/home/jobina/Documents/minproject/DRMS/DjangoV/lib/python3.10/site-packages/requests/sessions.py", line 703, in send
    r = adapter.send(request, **kwargs)
  File "/home/jobina/Documents/minproject/DRMS/DjangoV/lib/python3.10/site-packages/requests/adapters.py", line 698, in send
    raise SSLError(e, request=request)
requests.exceptions.SSLError: HTTPSConnectionPool(host='api.razorpay.com', port=443): Max retries exceeded with url: /v1/orders (Caused by SSLError(SSLCertVerificationError(1, '[SSL: CERTIFICATE_VERIFY_FAILED] certificate verify failed: self-signed certificate in certificate chain (_ssl.c:1007)')))

Internal Server Error: /package/5/process_booking/
Processing booking for package 5
Starting new HTTPS connection (3): api.razorpay.com:443
https://api.razorpay.com:443 "POST /v1/orders HTTP/11" 200 215
Processing booking for package 5
https://api.razorpay.com:443 "POST /v1/orders HTTP/11" 200 215
Processing booking for package 5
https://api.razorpay.com:443 "POST /v1/orders HTTP/11" 200 215
Internal Server Error: /verify-payment/
Traceback (most recent call last):
  File "/home/jobina/Documents/minproject/DRMS/DjangoV/lib/python3.10/site-packages/django/core/handlers/exception.py", line 55, in inner
    response = get_response(request)
  File "/home/jobina/Documents/minproject/DRMS/DjangoV/lib/python3.10/site-packages/django/core/handlers/base.py", line 197, in _get_response
    response = wrapped_callback(request, *callback_args, **callback_kwargs)
  File "/home/jobina/Documents/minproject/DRMS/DjangoV/lib/python3.10/site-packages/django/views/decorators/http.py", line 64, in inner
    return func(request, *args, **kwargs)
  File "/home/jobina/Documents/minproject/DRMS/daycation/adminpanal/views.py", line 737, in verify_payment
    payment_data = json.loads(request.body)
NameError: name 'json' is not defined
Processing booking for package 5
https://api.razorpay.com:443 "POST /v1/orders HTTP/11" 200 215
Internal Server Error: /verify-payment/
Traceback (most recent call last):
  File "/home/jobina/Documents/minproject/DRMS/DjangoV/lib/python3.10/site-packages/django/core/handlers/exception.py", line 55, in inner
    response = get_response(request)
  File "/home/jobina/Documents/minproject/DRMS/DjangoV/lib/python3.10/site-packages/django/core/handlers/base.py", line 197, in _get_response
    response = wrapped_callback(request, *callback_args, **callback_kwargs)
  File "/home/jobina/Documents/minproject/DRMS/DjangoV/lib/python3.10/site-packages/django/views/decorators/http.py", line 64, in inner
    return func(request, *args, **kwargs)
  File "/home/jobina/Documents/minproject/DRMS/daycation/adminpanal/views.py", line 737, in verify_payment
    payment_data = json.loads(request.body)
NameError: name 'json' is not defined
/home/jobina/Documents/minproject/DRMS/daycation/adminpanal/models.py changed, reloading.
Watching for file changes with StatReloader
/home/jobina/Documents/minproject/DRMS/daycation/adminpanal/models.py changed, reloading.
Watching for file changes with StatReloader
/home/jobina/Documents/minproject/DRMS/daycation/adminpanal/views.py changed, reloading.
Watching for file changes with StatReloader
Session data corrupted
Processing booking for package 5
Session data corrupted
Starting new HTTPS connection (1): api.razorpay.com:443
https://api.razorpay.com:443 "POST /v1/orders HTTP/11" 200 215
Session data corrupted
Internal Server Error: /verify-payment/
Traceback (most recent call last):
  File "/home/jobina/Documents/minproject/DRMS/DjangoV/lib/python3.10/site-packages/django/core/handlers/exception.py", line 55, in inner
    response = get_response(request)
  File "/home/jobina/Documents/minproject/DRMS/DjangoV/lib/python3.10/site-packages/django/core/handlers/base.py", line 197, in _get_response
    response = wrapped_callback(request, *callback_args, **callback_kwargs)
  File "/home/jobina/Documents/minproject/DRMS/DjangoV/lib/python3.10/site-packages/django/views/decorators/http.py", line 64, in inner
    return func(request, *args, **kwargs)
  File "/home/jobina/Documents/minproject/DRMS/daycation/adminpanal/views.py", line 737, in verify_payment
    payment_data = json.loads(request.body)
NameError: name 'json' is not defined
Session data corrupted
Session data corrupted
Session data corrupted
Session data corrupted
Processing booking for package 5
Session data corrupted
https://api.razorpay.com:443 "POST /v1/orders HTTP/11" 200 215
Session data corrupted
Internal Server Error: /verify-payment/
Traceback (most recent call last):
  File "/home/jobina/Documents/minproject/DRMS/DjangoV/lib/python3.10/site-packages/django/core/handlers/exception.py", line 55, in inner
    response = get_response(request)
  File "/home/jobina/Documents/minproject/DRMS/DjangoV/lib/python3.10/site-packages/django/core/handlers/base.py", line 197, in _get_response
    response = wrapped_callback(request, *callback_args, **callback_kwargs)
  File "/home/jobina/Documents/minproject/DRMS/DjangoV/lib/python3.10/site-packages/django/views/decorators/http.py", line 64, in inner
    return func(request, *args, **kwargs)
  File "/home/jobina/Documents/minproject/DRMS/daycation/adminpanal/views.py", line 737, in verify_payment
    payment_data = json.loads(request.body)
NameError: name 'json' is not defined
/home/jobina/Documents/minproject/DRMS/daycation/adminpanal/views.py changed, reloading.
Watching for file changes with StatReloader
/home/jobina/Documents/minproject/DRMS/daycation/adminpanal/views.py changed, reloading.
Watching for file changes with StatReloader
/home/jobina/Documents/minproject/DRMS/daycation/adminpanal/views.py changed, reloading.
Watching for file changes with StatReloader
Processing booking for package 5
Session data corrupted
Starting new HTTPS connection (1): api.razorpay.com:443
https://api.razorpay.com:443 "POST /v1/orders HTTP/11" 200 215
Session data corrupted
Internal Server Error: /package/5/book/
Traceback (most recent call last):
  File "/home/jobina/Documents/minproject/DRMS/DjangoV/lib/python3.10/site-packages/django/core/handlers/exception.py", line 55, in inner
    response = get_response(request)
  File "/home/jobina/Documents/minproject/DRMS/DjangoV/lib/python3.10/site-packages/django/core/handlers/base.py", line 197, in _get_response
    response = wrapped_callback(request, *callback_args, **callback_kwargs)
  File "/home/jobina/Documents/minproject/DRMS/daycation/adminpanal/views.py", line 559, in book_package
    return render(request, 'book_package.html', context)
  File "/home/jobina/Documents/minproject/DRMS/DjangoV/lib/python3.10/site-packages/django/shortcuts.py", line 25, in render
    content = loader.render_to_string(template_name, context, request, using=using)
  File "/home/jobina/Documents/minproject/DRMS/DjangoV/lib/python3.10/site-packages/django/template/loader.py", line 62, in render_to_string
    return template.render(context, request)
  File "/home/jobina/Documents/minproject/DRMS/DjangoV/lib/python3.10/site-packages/django/template/backends/django.py", line 107, in render
    return self.template.render(context)
  File "/home/jobina/Documents/minproject/DRMS/DjangoV/lib/python3.10/site-packages/django/template/base.py", line 171, in render
    return self._render(context)
  File "/home/jobina/Documents/minproject/DRMS/DjangoV/lib/python3.10/site-packages/django/template/base.py", line 163, in _render
    return self.nodelist.render(context)
  File "/home/jobina/Documents/minproject/DRMS/DjangoV/lib/python3.10/site-packages/django/template/base.py", line 1008, in render
    return SafeString("".join([node.render_annotated(context) for node in self]))
  File "/home/jobina/Documents/minproject/DRMS/DjangoV/lib/python3.10/site-packages/django/template/base.py", line 1008, in <listcomp>
    return SafeString("".join([node.render_annotated(context) for node in self]))
  File "/home/jobina/Documents/minproject/DRMS/DjangoV/lib/python3.10/site-packages/django/template/base.py", line 969, in render_annotated
    return self.render(context)
  File "/home/jobina/Documents/minproject/DRMS/DjangoV/lib/python3.10/site-packages/django/template/loader_tags.py", line 159, in render
    return compiled_parent._render(context)
  File "/home/jobina/Documents/minproject/DRMS/DjangoV/lib/python3.10/site-packages/django/template/base.py", line 163, in _render
    return self.nodelist.render(context)
  File "/home/jobina/Documents/minproject/DRMS/DjangoV/lib/python3.10/site-packages/django/template/base.py", line 1008, in render
    return SafeString("".join([node.render_annotated(context) for node in self]))
  File "/home/jobina/Documents/minproject/DRMS/DjangoV/lib/python3.10/site-packages/django/template/base.py", line 1008, in <listcomp>
    return SafeString("".join([node.render_annotated(context) for node in self]))
  File "/home/jobina/Documents/minproject/DRMS/DjangoV/lib/python3.10/site-packages/django/template/base.py", line 969, in render_annotated
    return self.render(context)
  File "/home/jobina/Documents/minproject/DRMS/DjangoV/lib/python3.10/site-packages/django/template/loader_tags.py", line 65, in render
    result = block.nodelist.render(context)
  File "/home/jobina/Documents/minproject/DRMS/DjangoV/lib/python3.10/site-packages/django/template/base.py", line 1008, in render
    return SafeString("".join([node.render_annotated(context) for node in self]))
  File "/home/jobina/Documents/minproject/DRMS/DjangoV/lib/python3.10/site-packages/django/template/base.py", line 1008, in <listcomp>
    return SafeString("".join([node.render_annotated(context) for node in self]))
  File "/home/jobina/Documents/minproject/DRMS/DjangoV/lib/python3.10/site-packages/django/template/base.py", line 969, in render_annotated
    return self.render(context)
  File "/home/jobina/Documents/minproject/DRMS/DjangoV/lib/python3.10/site-packages/django/template/defaulttags.py", line 480, in render
    url = reverse(view_name, args=args, kwargs=kwargs, current_app=current_app)
  File "/home/jobina/Documents/minproject/DRMS/DjangoV/lib/python3.10/site-packages/django/urls/base.py", line 88, in reverse
    return resolver._reverse_with_prefix(view, prefix, *args, **kwargs)
  File "/home/jobina/Documents/minproject/DRMS/DjangoV/lib/python3.10/site-packages/django/urls/resolvers.py", line 831, in _reverse_with_prefix
    raise NoReverseMatch(msg)
django.urls.exceptions.NoReverseMatch: Reverse for 'daycation_package_details' with no arguments not found. 1 pattern(s) tried: ['daycation/(?P<package_id>[0-9]+)/\\Z']
Session data corrupted
Internal Server Error: /package/5/book/
Traceback (most recent call last):
  File "/home/jobina/Documents/minproject/DRMS/DjangoV/lib/python3.10/site-packages/django/core/handlers/exception.py", line 55, in inner
    response = get_response(request)
  File "/home/jobina/Documents/minproject/DRMS/DjangoV/lib/python3.10/site-packages/django/core/handlers/base.py", line 197, in _get_response
    response = wrapped_callback(request, *callback_args, **callback_kwargs)
  File "/home/jobina/Documents/minproject/DRMS/daycation/adminpanal/views.py", line 559, in book_package
    return render(request, 'book_package.html', context)
  File "/home/jobina/Documents/minproject/DRMS/DjangoV/lib/python3.10/site-packages/django/shortcuts.py", line 25, in render
    content = loader.render_to_string(template_name, context, request, using=using)
  File "/home/jobina/Documents/minproject/DRMS/DjangoV/lib/python3.10/site-packages/django/template/loader.py", line 62, in render_to_string
    return template.render(context, request)
  File "/home/jobina/Documents/minproject/DRMS/DjangoV/lib/python3.10/site-packages/django/template/backends/django.py", line 107, in render
    return self.template.render(context)
  File "/home/jobina/Documents/minproject/DRMS/DjangoV/lib/python3.10/site-packages/django/template/base.py", line 171, in render
    return self._render(context)
  File "/home/jobina/Documents/minproject/DRMS/DjangoV/lib/python3.10/site-packages/django/template/base.py", line 163, in _render
    return self.nodelist.render(context)
  File "/home/jobina/Documents/minproject/DRMS/DjangoV/lib/python3.10/site-packages/django/template/base.py", line 1008, in render
    return SafeString("".join([node.render_annotated(context) for node in self]))
  File "/home/jobina/Documents/minproject/DRMS/DjangoV/lib/python3.10/site-packages/django/template/base.py", line 1008, in <listcomp>
    return SafeString("".join([node.render_annotated(context) for node in self]))
  File "/home/jobina/Documents/minproject/DRMS/DjangoV/lib/python3.10/site-packages/django/template/base.py", line 969, in render_annotated
    return self.render(context)
  File "/home/jobina/Documents/minproject/DRMS/DjangoV/lib/python3.10/site-packages/django/template/loader_tags.py", line 159, in render
    return compiled_parent._render(context)
  File "/home/jobina/Documents/minproject/DRMS/DjangoV/lib/python3.10/site-packages/django/template/base.py", line 163, in _render
    return self.nodelist.render(context)
  File "/home/jobina/Documents/minproject/DRMS/DjangoV/lib/python3.10/site-packages/django/template/base.py", line 1008, in render
    return SafeString("".join([node.render_annotated(context) for node in self]))
  File "/home/jobina/Documents/minproject/DRMS/DjangoV/lib/python3.10/site-packages/django/template/base.py", line 1008, in <listcomp>
    return SafeString("".join([node.render_annotated(context) for node in self]))
  File "/home/jobina/Documents/minproject/DRMS/DjangoV/lib/python3.10/site-packages/django/template/base.py", line 969, in render_annotated
    return self.render(context)
  File "/home/jobina/Documents/minproject/DRMS/DjangoV/lib/python3.10/site-packages/django/template/loader_tags.py", line 65, in render
    result = block.nodelist.render(context)
  File "/home/jobina/Documents/minproject/DRMS/DjangoV/lib/python3.10/site-packages/django/template/base.py", line 1008, in render
    return SafeString("".join([node.render_annotated(context) for node in self]))
  File "/home/jobina/Documents/minproject/DRMS/DjangoV/lib/python3.10/site-packages/django/template/base.py", line 1008, in <listcomp>
    return SafeString("".join([node.render_annotated(context) for node in self]))
  File "/home/jobina/Documents/minproject/DRMS/DjangoV/lib/python3.10/site-packages/django/template/base.py", line 969, in render_annotated
    return self.render(context)
  File "/home/jobina/Documents/minproject/DRMS/DjangoV/lib/python3.10/site-packages/django/template/defaulttags.py", line 480, in render
    url = reverse(view_name, args=args, kwargs=kwargs, current_app=current_app)
  File "/home/jobina/Documents/minproject/DRMS/DjangoV/lib/python3.10/site-packages/django/urls/base.py", line 88, in reverse
    return resolver._reverse_with_prefix(view, prefix, *args, **kwargs)
  File "/home/jobina/Documents/minproject/DRMS/DjangoV/lib/python3.10/site-packages/django/urls/resolvers.py", line 831, in _reverse_with_prefix
    raise NoReverseMatch(msg)
django.urls.exceptions.NoReverseMatch: Reverse for 'userindex.html' not found. 'userindex.html' is not a valid view function or pattern name.
Session data corrupted
Internal Server Error: /package/5/book/
Traceback (most recent call last):
  File "/home/jobina/Documents/minproject/DRMS/DjangoV/lib/python3.10/site-packages/django/core/handlers/exception.py", line 55, in inner
    response = get_response(request)
  File "/home/jobina/Documents/minproject/DRMS/DjangoV/lib/python3.10/site-packages/django/core/handlers/base.py", line 197, in _get_response
    response = wrapped_callback(request, *callback_args, **callback_kwargs)
  File "/home/jobina/Documents/minproject/DRMS/daycation/adminpanal/views.py", line 559, in book_package
    return render(request, 'book_package.html', context)
  File "/home/jobina/Documents/minproject/DRMS/DjangoV/lib/python3.10/site-packages/django/shortcuts.py", line 25, in render
    content = loader.render_to_string(template_name, context, request, using=using)
  File "/home/jobina/Documents/minproject/DRMS/DjangoV/lib/python3.10/site-packages/django/template/loader.py", line 62, in render_to_string
    return template.render(context, request)
  File "/home/jobina/Documents/minproject/DRMS/DjangoV/lib/python3.10/site-packages/django/template/backends/django.py", line 107, in render
    return self.template.render(context)
  File "/home/jobina/Documents/minproject/DRMS/DjangoV/lib/python3.10/site-packages/django/template/base.py", line 171, in render
    return self._render(context)
  File "/home/jobina/Documents/minproject/DRMS/DjangoV/lib/python3.10/site-packages/django/template/base.py", line 163, in _render
    return self.nodelist.render(context)
  File "/home/jobina/Documents/minproject/DRMS/DjangoV/lib/python3.10/site-packages/django/template/base.py", line 1008, in render
    return SafeString("".join([node.render_annotated(context) for node in self]))
  File "/home/jobina/Documents/minproject/DRMS/DjangoV/lib/python3.10/site-packages/django/template/base.py", line 1008, in <listcomp>
    return SafeString("".join([node.render_annotated(context) for node in self]))
  File "/home/jobina/Documents/minproject/DRMS/DjangoV/lib/python3.10/site-packages/django/template/base.py", line 969, in render_annotated
    return self.render(context)
  File "/home/jobina/Documents/minproject/DRMS/DjangoV/lib/python3.10/site-packages/django/template/loader_tags.py", line 159, in render
    return compiled_parent._render(context)
  File "/home/jobina/Documents/minproject/DRMS/DjangoV/lib/python3.10/site-packages/django/template/base.py", line 163, in _render
    return self.nodelist.render(context)
  File "/home/jobina/Documents/minproject/DRMS/DjangoV/lib/python3.10/site-packages/django/template/base.py", line 1008, in render
    return SafeString("".join([node.render_annotated(context) for node in self]))
  File "/home/jobina/Documents/minproject/DRMS/DjangoV/lib/python3.10/site-packages/django/template/base.py", line 1008, in <listcomp>
    return SafeString("".join([node.render_annotated(context) for node in self]))
  File "/home/jobina/Documents/minproject/DRMS/DjangoV/lib/python3.10/site-packages/django/template/base.py", line 969, in render_annotated
    return self.render(context)
  File "/home/jobina/Documents/minproject/DRMS/DjangoV/lib/python3.10/site-packages/django/template/loader_tags.py", line 65, in render
    result = block.nodelist.render(context)
  File "/home/jobina/Documents/minproject/DRMS/DjangoV/lib/python3.10/site-packages/django/template/base.py", line 1008, in render
    return SafeString("".join([node.render_annotated(context) for node in self]))
  File "/home/jobina/Documents/minproject/DRMS/DjangoV/lib/python3.10/site-packages/django/template/base.py", line 1008, in <listcomp>
    return SafeString("".join([node.render_annotated(context) for node in self]))
  File "/home/jobina/Documents/minproject/DRMS/DjangoV/lib/python3.10/site-packages/django/template/base.py", line 969, in render_annotated
    return self.render(context)
  File "/home/jobina/Documents/minproject/DRMS/DjangoV/lib/python3.10/site-packages/django/template/defaulttags.py", line 480, in render
    url = reverse(view_name, args=args, kwargs=kwargs, current_app=current_app)
  File "/home/jobina/Documents/minproject/DRMS/DjangoV/lib/python3.10/site-packages/django/urls/base.py", line 88, in reverse
    return resolver._reverse_with_prefix(view, prefix, *args, **kwargs)
  File "/home/jobina/Documents/minproject/DRMS/DjangoV/lib/python3.10/site-packages/django/urls/resolvers.py", line 831, in _reverse_with_prefix
    raise NoReverseMatch(msg)
django.urls.exceptions.NoReverseMatch: Reverse for 'userindex.html' not found. 'userindex.html' is not a valid view function or pattern name.
Session data corrupted
Processing booking for package 5
Session data corrupted
https://api.razorpay.com:443 "POST /v1/orders HTTP/11" 200 215
Bad Request: /verify-payment/
Session data corrupted
Session data corrupted
Session data corrupted
Processing booking for package 5
Session data corrupted
https://api.razorpay.com:443 "POST /v1/orders HTTP/11" 200 215
Bad Request: /verify-payment/
Session data corrupted
Session data corrupted
Session data corrupted
Session data corrupted
Watching for file changes with StatReloader
Internal Server Error: /adminindex/
Traceback (most recent call last):
  File "/home/jobina/Documents/minproject/DRMS/DjangoV/lib/python3.10/site-packages/django/core/handlers/exception.py", line 55, in inner
    response = get_response(request)
  File "/home/jobina/Documents/minproject/DRMS/DjangoV/lib/python3.10/site-packages/django/core/handlers/base.py", line 197, in _get_response
    response = wrapped_callback(request, *callback_args, **callback_kwargs)
  File "/home/jobina/Documents/minproject/DRMS/daycation/adminpanal/views.py", line 63, in admin_index
    return render(request, 'adminindex.html')
  File "/home/jobina/Documents/minproject/DRMS/DjangoV/lib/python3.10/site-packages/django/shortcuts.py", line 25, in render
    content = loader.render_to_string(template_name, context, request, using=using)
  File "/home/jobina/Documents/minproject/DRMS/DjangoV/lib/python3.10/site-packages/django/template/loader.py", line 62, in render_to_string
    return template.render(context, request)
  File "/home/jobina/Documents/minproject/DRMS/DjangoV/lib/python3.10/site-packages/django/template/backends/django.py", line 107, in render
    return self.template.render(context)
  File "/home/jobina/Documents/minproject/DRMS/DjangoV/lib/python3.10/site-packages/django/template/base.py", line 171, in render
    return self._render(context)
  File "/home/jobina/Documents/minproject/DRMS/DjangoV/lib/python3.10/site-packages/django/template/base.py", line 163, in _render
    return self.nodelist.render(context)
  File "/home/jobina/Documents/minproject/DRMS/DjangoV/lib/python3.10/site-packages/django/template/base.py", line 1008, in render
    return SafeString("".join([node.render_annotated(context) for node in self]))
  File "/home/jobina/Documents/minproject/DRMS/DjangoV/lib/python3.10/site-packages/django/template/base.py", line 1008, in <listcomp>
    return SafeString("".join([node.render_annotated(context) for node in self]))
  File "/home/jobina/Documents/minproject/DRMS/DjangoV/lib/python3.10/site-packages/django/template/base.py", line 969, in render_annotated
    return self.render(context)
  File "/home/jobina/Documents/minproject/DRMS/DjangoV/lib/python3.10/site-packages/django/template/defaulttags.py", line 480, in render
    url = reverse(view_name, args=args, kwargs=kwargs, current_app=current_app)
  File "/home/jobina/Documents/minproject/DRMS/DjangoV/lib/python3.10/site-packages/django/urls/base.py", line 88, in reverse
    return resolver._reverse_with_prefix(view, prefix, *args, **kwargs)
  File "/home/jobina/Documents/minproject/DRMS/DjangoV/lib/python3.10/site-packages/django/urls/resolvers.py", line 831, in _reverse_with_prefix
    raise NoReverseMatch(msg)
django.urls.exceptions.NoReverseMatch: Reverse for 'menumanagement' not found. 'menumanagement' is not a valid view function or pattern name.
Session data corrupted
Session data corrupted
Session data corrupted
Session data corrupted
Session data corrupted
Session data corrupted
Session data corrupted
Session data corrupted
Session data corrupted
Session data corrupted
Processing booking for package 5
Starting new HTTPS connection (1): api.razorpay.com:443
https://api.razorpay.com:443 "POST /v1/orders HTTP/11" 200 215
Bad Request: /verify-payment/
Processing booking for package 5
https://api.razorpay.com:443 "POST /v1/orders HTTP/11" 200 215
Processing booking for package 5
https://api.razorpay.com:443 "POST /v1/orders HTTP/11" 200 215
Processing booking for package 5
Processing booking for package 5
Starting new HTTPS connection (2): api.razorpay.com:443
https://api.razorpay.com:443 "POST /v1/orders HTTP/11" 200 215
Processing booking for package 5
Processing booking for package 5
Starting new HTTPS connection (3): api.razorpay.com:443
https://api.razorpay.com:443 "POST /v1/orders HTTP/11" 200 215
Processing booking for package 5
https://api.razorpay.com:443 "POST /v1/orders HTTP/11" 200 215
https://api.razorpay.com:443 "POST /v1/orders HTTP/11" 200 215
Processing booking for package 5
Error processing booking: ('Connection aborted.', RemoteDisconnected('Remote end closed connection without response'))
Traceback (most recent call last):
  File "/home/jobina/Documents/minproject/DRMS/DjangoV/lib/python3.10/site-packages/urllib3/connectionpool.py", line 789, in urlopen
    response = self._make_request(
  File "/home/jobina/Documents/minproject/DRMS/DjangoV/lib/python3.10/site-packages/urllib3/connectionpool.py", line 536, in _make_request
    response = conn.getresponse()
  File "/home/jobina/Documents/minproject/DRMS/DjangoV/lib/python3.10/site-packages/urllib3/connection.py", line 464, in getresponse
    httplib_response = super().getresponse()
  File "/usr/lib/python3.10/http/client.py", line 1375, in getresponse
    response.begin()
  File "/usr/lib/python3.10/http/client.py", line 318, in begin
    version, status, reason = self._read_status()
  File "/usr/lib/python3.10/http/client.py", line 287, in _read_status
    raise RemoteDisconnected("Remote end closed connection without"
http.client.RemoteDisconnected: Remote end closed connection without response

During handling of the above exception, another exception occurred:

Traceback (most recent call last):
  File "/home/jobina/Documents/minproject/DRMS/DjangoV/lib/python3.10/site-packages/requests/adapters.py", line 667, in send
    resp = conn.urlopen(
  File "/home/jobina/Documents/minproject/DRMS/DjangoV/lib/python3.10/site-packages/urllib3/connectionpool.py", line 843, in urlopen
    retries = retries.increment(
  File "/home/jobina/Documents/minproject/DRMS/DjangoV/lib/python3.10/site-packages/urllib3/util/retry.py", line 474, in increment
    raise reraise(type(error), error, _stacktrace)
  File "/home/jobina/Documents/minproject/DRMS/DjangoV/lib/python3.10/site-packages/urllib3/util/util.py", line 38, in reraise
    raise value.with_traceback(tb)
  File "/home/jobina/Documents/minproject/DRMS/DjangoV/lib/python3.10/site-packages/urllib3/connectionpool.py", line 789, in urlopen
    response = self._make_request(
  File "/home/jobina/Documents/minproject/DRMS/DjangoV/lib/python3.10/site-packages/urllib3/connectionpool.py", line 536, in _make_request
    response = conn.getresponse()
  File "/home/jobina/Documents/minproject/DRMS/DjangoV/lib/python3.10/site-packages/urllib3/connection.py", line 464, in getresponse
    httplib_response = super().getresponse()
  File "/usr/lib/python3.10/http/client.py", line 1375, in getresponse
    response.begin()
  File "/usr/lib/python3.10/http/client.py", line 318, in begin
    version, status, reason = self._read_status()
  File "/usr/lib/python3.10/http/client.py", line 287, in _read_status
    raise RemoteDisconnected("Remote end closed connection without"
urllib3.exceptions.ProtocolError: ('Connection aborted.', RemoteDisconnected('Remote end closed connection without response'))

During handling of the above exception, another exception occurred:

Traceback (most recent call last):
  File "/home/jobina/Documents/minproject/DRMS/daycation/adminpanal/views.py", line 607, in process_booking
    razorpay_order = client.order.create({
  File "/home/jobina/Documents/minproject/DRMS/DjangoV/lib/python3.10/site-packages/razorpay/resources/order.py", line 71, in create
    return self.post_url(url, data, **kwargs)
  File "/home/jobina/Documents/minproject/DRMS/DjangoV/lib/python3.10/site-packages/razorpay/resources/base.py", line 20, in post_url
    return self.client.post(url, data, **kwargs)
  File "/home/jobina/Documents/minproject/DRMS/DjangoV/lib/python3.10/site-packages/razorpay/client.py", line 156, in post
    return self.request('post', path, data=data, **options)
  File "/home/jobina/Documents/minproject/DRMS/DjangoV/lib/python3.10/site-packages/razorpay/client.py", line 120, in request
    response = getattr(self.session, method)(url, auth=self.auth,
  File "/home/jobina/Documents/minproject/DRMS/DjangoV/lib/python3.10/site-packages/requests/sessions.py", line 637, in post
    return self.request("POST", url, data=data, json=json, **kwargs)
  File "/home/jobina/Documents/minproject/DRMS/DjangoV/lib/python3.10/site-packages/requests/sessions.py", line 589, in request
    resp = self.send(prep, **send_kwargs)
  File "/home/jobina/Documents/minproject/DRMS/DjangoV/lib/python3.10/site-packages/requests/sessions.py", line 703, in send
    r = adapter.send(request, **kwargs)
  File "/home/jobina/Documents/minproject/DRMS/DjangoV/lib/python3.10/site-packages/requests/adapters.py", line 682, in send
    raise ConnectionError(err, request=request)
requests.exceptions.ConnectionError: ('Connection aborted.', RemoteDisconnected('Remote end closed connection without response'))

Internal Server Error: /package/5/process_booking/
Processing booking for package 5
Starting new HTTPS connection (4): api.razorpay.com:443
https://api.razorpay.com:443 "POST /v1/orders HTTP/11" 200 215
Processing booking for package 5
https://api.razorpay.com:443 "POST /v1/orders HTTP/11" 200 215
Processing booking for package 5
https://api.razorpay.com:443 "POST /v1/orders HTTP/11" 200 215
Bad Request: /verify-payment/
Error processing booking: ('Connection aborted.', RemoteDisconnected('Remote end closed connection without response'))
Traceback (most recent call last):
  File "/home/jobina/Documents/minproject/DRMS/DjangoV/lib/python3.10/site-packages/urllib3/connectionpool.py", line 789, in urlopen
    response = self._make_request(
  File "/home/jobina/Documents/minproject/DRMS/DjangoV/lib/python3.10/site-packages/urllib3/connectionpool.py", line 536, in _make_request
    response = conn.getresponse()
  File "/home/jobina/Documents/minproject/DRMS/DjangoV/lib/python3.10/site-packages/urllib3/connection.py", line 464, in getresponse
    httplib_response = super().getresponse()
  File "/usr/lib/python3.10/http/client.py", line 1375, in getresponse
    response.begin()
  File "/usr/lib/python3.10/http/client.py", line 318, in begin
    version, status, reason = self._read_status()
  File "/usr/lib/python3.10/http/client.py", line 287, in _read_status
    raise RemoteDisconnected("Remote end closed connection without"
http.client.RemoteDisconnected: Remote end closed connection without response

During handling of the above exception, another exception occurred:

Traceback (most recent call last):
  File "/home/jobina/Documents/minproject/DRMS/DjangoV/lib/python3.10/site-packages/requests/adapters.py", line 667, in send
    resp = conn.urlopen(
  File "/home/jobina/Documents/minproject/DRMS/DjangoV/lib/python3.10/site-packages/urllib3/connectionpool.py", line 843, in urlopen
    retries = retries.increment(
  File "/home/jobina/Documents/minproject/DRMS/DjangoV/lib/python3.10/site-packages/urllib3/util/retry.py", line 474, in increment
    raise reraise(type(error), error, _stacktrace)
  File "/home/jobina/Documents/minproject/DRMS/DjangoV/lib/python3.10/site-packages/urllib3/util/util.py", line 38, in reraise
    raise value.with_traceback(tb)
  File "/home/jobina/Documents/minproject/DRMS/DjangoV/lib/python3.10/site-packages/urllib3/connectionpool.py", line 789, in urlopen
    response = self._make_request(
  File "/home/jobina/Documents/minproject/DRMS/DjangoV/lib/python3.10/site-packages/urllib3/connectionpool.py", line 536, in _make_request
    response = conn.getresponse()
  File "/home/jobina/Documents/minproject/DRMS/DjangoV/lib/python3.10/site-packages/urllib3/connection.py", line 464, in getresponse
    httplib_response = super().getresponse()
  File "/usr/lib/python3.10/http/client.py", line 1375, in getresponse
    response.begin()
  File "/usr/lib/python3.10/http/client.py", line 318, in begin
    version, status, reason = self._read_status()
  File "/usr/lib/python3.10/http/client.py", line 287, in _read_status
    raise RemoteDisconnected("Remote end closed connection without"
urllib3.exceptions.ProtocolError: ('Connection aborted.', RemoteDisconnected('Remote end closed connection without response'))

During handling of the above exception, another exception occurred:

Traceback (most recent call last):
  File "/home/jobina/Documents/minproject/DRMS/daycation/adminpanal/views.py", line 607, in process_booking
    razorpay_order = client.order.create({
  File "/home/jobina/Documents/minproject/DRMS/DjangoV/lib/python3.10/site-packages/razorpay/resources/order.py", line 71, in create
    return self.post_url(url, data, **kwargs)
  File "/home/jobina/Documents/minproject/DRMS/DjangoV/lib/python3.10/site-packages/razorpay/resources/base.py", line 20, in post_url
    return self.client.post(url, data, **kwargs)
  File "/home/jobina/Documents/minproject/DRMS/DjangoV/lib/python3.10/site-packages/razorpay/client.py", line 156, in post
    return self.request('post', path, data=data, **options)
  File "/home/jobina/Documents/minproject/DRMS/DjangoV/lib/python3.10/site-packages/razorpay/client.py", line 120, in request
    response = getattr(self.session, method)(url, auth=self.auth,
  File "/home/jobina/Documents/minproject/DRMS/DjangoV/lib/python3.10/site-packages/requests/sessions.py", line 637, in post
    return self.request("POST", url, data=data, json=json, **kwargs)
  File "/home/jobina/Documents/minproject/DRMS/DjangoV/lib/python3.10/site-packages/requests/sessions.py", line 589, in request
    resp = self.send(prep, **send_kwargs)
  File "/home/jobina/Documents/minproject/DRMS/DjangoV/lib/python3.10/site-packages/requests/sessions.py", line 703, in send
    r = adapter.send(request, **kwargs)
  File "/home/jobina/Documents/minproject/DRMS/DjangoV/lib/python3.10/site-packages/requests/adapters.py", line 682, in send
    raise ConnectionError(err, request=request)
requests.exceptions.ConnectionError: ('Connection aborted.', RemoteDisconnected('Remote end closed connection without response'))

Internal Server Error: /package/5/process_booking/
Internal Server Error: /userregister/
Traceback (most recent call last):
  File "/home/jobina/Documents/minproject/DRMS/DjangoV/lib/python3.10/site-packages/django/template/base.py", line 510, in parse
    compile_func = self.tags[command]
KeyError: 'static'

During handling of the above exception, another exception occurred:

Traceback (most recent call last):
  File "/home/jobina/Documents/minproject/DRMS/DjangoV/lib/python3.10/site-packages/django/core/handlers/exception.py", line 55, in inner
    response = get_response(request)
  File "/home/jobina/Documents/minproject/DRMS/DjangoV/lib/python3.10/site-packages/django/core/handlers/base.py", line 197, in _get_response
    response = wrapped_callback(request, *callback_args, **callback_kwargs)
  File "/home/jobina/Documents/minproject/DRMS/daycation/userapp/views.py", line 342, in userregister
    return render(request, 'userregister.html')
  File "/home/jobina/Documents/minproject/DRMS/DjangoV/lib/python3.10/site-packages/django/shortcuts.py", line 25, in render
    content = loader.render_to_string(template_name, context, request, using=using)
  File "/home/jobina/Documents/minproject/DRMS/DjangoV/lib/python3.10/site-packages/django/template/loader.py", line 61, in render_to_string
    template = get_template(template_name, using=using)
  File "/home/jobina/Documents/minproject/DRMS/DjangoV/lib/python3.10/site-packages/django/template/loader.py", line 15, in get_template
    return engine.get_template(template_name)
  File "/home/jobina/Documents/minproject/DRMS/DjangoV/lib/python3.10/site-packages/django/template/backends/django.py", line 79, in get_template
    return Template(self.engine.get_template(template_name), self)
  File "/home/jobina/Documents/minproject/DRMS/DjangoV/lib/python3.10/site-packages/django/template/engine.py", line 177, in get_template
    template, origin = self.find_template(template_name)
  File "/home/jobina/Documents/minproject/DRMS/DjangoV/lib/python3.10/site-packages/django/template/engine.py", line 159, in find_template
    template = loader.get_template(name, skip=skip)
  File "/home/jobina/Documents/minproject/DRMS/DjangoV/lib/python3.10/site-packages/django/template/loaders/cached.py", line 57, in get_template
    template = super().get_template(template_name, skip)
  File "/home/jobina/Documents/minproject/DRMS/DjangoV/lib/python3.10/site-packages/django/template/loaders/base.py", line 28, in get_template
    return Template(
  File "/home/jobina/Documents/minproject/DRMS/DjangoV/lib/python3.10/site-packages/django/template/base.py", line 154, in __init__
    self.nodelist = self.compile_nodelist()
  File "/home/jobina/Documents/minproject/DRMS/DjangoV/lib/python3.10/site-packages/django/template/base.py", line 196, in compile_nodelist
    nodelist = parser.parse()
  File "/home/jobina/Documents/minproject/DRMS/DjangoV/lib/python3.10/site-packages/django/template/base.py", line 512, in parse
    self.invalid_block_tag(token, command, parse_until)
  File "/home/jobina/Documents/minproject/DRMS/DjangoV/lib/python3.10/site-packages/django/template/base.py", line 573, in invalid_block_tag
    raise self.error(
django.template.exceptions.TemplateSyntaxError: Invalid block tag on line 130: 'static'. Did you forget to register or load this tag?
Internal Server Error: /userregister/
Traceback (most recent call last):
  File "/home/jobina/Documents/minproject/DRMS/DjangoV/lib/python3.10/site-packages/django/template/base.py", line 510, in parse
    compile_func = self.tags[command]
KeyError: 'static'

During handling of the above exception, another exception occurred:

Traceback (most recent call last):
  File "/home/jobina/Documents/minproject/DRMS/DjangoV/lib/python3.10/site-packages/django/core/handlers/exception.py", line 55, in inner
    response = get_response(request)
  File "/home/jobina/Documents/minproject/DRMS/DjangoV/lib/python3.10/site-packages/django/core/handlers/base.py", line 197, in _get_response
    response = wrapped_callback(request, *callback_args, **callback_kwargs)
  File "/home/jobina/Documents/minproject/DRMS/daycation/userapp/views.py", line 342, in userregister
    return render(request, 'userregister.html')
  File "/home/jobina/Documents/minproject/DRMS/DjangoV/lib/python3.10/site-packages/django/shortcuts.py", line 25, in render
    content = loader.render_to_string(template_name, context, request, using=using)
  File "/home/jobina/Documents/minproject/DRMS/DjangoV/lib/python3.10/site-packages/django/template/loader.py", line 61, in render_to_string
    template = get_template(template_name, using=using)
  File "/home/jobina/Documents/minproject/DRMS/DjangoV/lib/python3.10/site-packages/django/template/loader.py", line 15, in get_template
    return engine.get_template(template_name)
  File "/home/jobina/Documents/minproject/DRMS/DjangoV/lib/python3.10/site-packages/django/template/backends/django.py", line 79, in get_template
    return Template(self.engine.get_template(template_name), self)
  File "/home/jobina/Documents/minproject/DRMS/DjangoV/lib/python3.10/site-packages/django/template/engine.py", line 177, in get_template
    template, origin = self.find_template(template_name)
  File "/home/jobina/Documents/minproject/DRMS/DjangoV/lib/python3.10/site-packages/django/template/engine.py", line 159, in find_template
    template = loader.get_template(name, skip=skip)
  File "/home/jobina/Documents/minproject/DRMS/DjangoV/lib/python3.10/site-packages/django/template/loaders/cached.py", line 57, in get_template
    template = super().get_template(template_name, skip)
  File "/home/jobina/Documents/minproject/DRMS/DjangoV/lib/python3.10/site-packages/django/template/loaders/base.py", line 28, in get_template
    return Template(
  File "/home/jobina/Documents/minproject/DRMS/DjangoV/lib/python3.10/site-packages/django/template/base.py", line 154, in __init__
    self.nodelist = self.compile_nodelist()
  File "/home/jobina/Documents/minproject/DRMS/DjangoV/lib/python3.10/site-packages/django/template/base.py", line 196, in compile_nodelist
    nodelist = parser.parse()
  File "/home/jobina/Documents/minproject/DRMS/DjangoV/lib/python3.10/site-packages/django/template/base.py", line 512, in parse
    self.invalid_block_tag(token, command, parse_until)
  File "/home/jobina/Documents/minproject/DRMS/DjangoV/lib/python3.10/site-packages/django/template/base.py", line 573, in invalid_block_tag
    raise self.error(
django.template.exceptions.TemplateSyntaxError: Invalid block tag on line 122: 'static'. Did you forget to register or load this tag?
Internal Server Error: /userregister/
Traceback (most recent call last):
  File "/home/jobina/Documents/minproject/DRMS/DjangoV/lib/python3.10/site-packages/django/template/base.py", line 510, in parse
    compile_func = self.tags[command]
KeyError: 'static'

During handling of the above exception, another exception occurred:

Traceback (most recent call last):
  File "/home/jobina/Documents/minproject/DRMS/DjangoV/lib/python3.10/site-packages/django/core/handlers/exception.py", line 55, in inner
    response = get_response(request)
  File "/home/jobina/Documents/minproject/DRMS/DjangoV/lib/python3.10/site-packages/django/core/handlers/base.py", line 197, in _get_response
    response = wrapped_callback(request, *callback_args, **callback_kwargs)
  File "/home/jobina/Documents/minproject/DRMS/daycation/userapp/views.py", line 342, in userregister
    return render(request, 'userregister.html')
  File "/home/jobina/Documents/minproject/DRMS/DjangoV/lib/python3.10/site-packages/django/shortcuts.py", line 25, in render
    content = loader.render_to_string(template_name, context, request, using=using)
  File "/home/jobina/Documents/minproject/DRMS/DjangoV/lib/python3.10/site-packages/django/template/loader.py", line 61, in render_to_string
    template = get_template(template_name, using=using)
  File "/home/jobina/Documents/minproject/DRMS/DjangoV/lib/python3.10/site-packages/django/template/loader.py", line 15, in get_template
    return engine.get_template(template_name)
  File "/home/jobina/Documents/minproject/DRMS/DjangoV/lib/python3.10/site-packages/django/template/backends/django.py", line 79, in get_template
    return Template(self.engine.get_template(template_name), self)
  File "/home/jobina/Documents/minproject/DRMS/DjangoV/lib/python3.10/site-packages/django/template/engine.py", line 177, in get_template
    template, origin = self.find_template(template_name)
  File "/home/jobina/Documents/minproject/DRMS/DjangoV/lib/python3.10/site-packages/django/template/engine.py", line 159, in find_template
    template = loader.get_template(name, skip=skip)
  File "/home/jobina/Documents/minproject/DRMS/DjangoV/lib/python3.10/site-packages/django/template/loaders/cached.py", line 57, in get_template
    template = super().get_template(template_name, skip)
  File "/home/jobina/Documents/minproject/DRMS/DjangoV/lib/python3.10/site-packages/django/template/loaders/base.py", line 28, in get_template
    return Template(
  File "/home/jobina/Documents/minproject/DRMS/DjangoV/lib/python3.10/site-packages/django/template/base.py", line 154, in __init__
    self.nodelist = self.compile_nodelist()
  File "/home/jobina/Documents/minproject/DRMS/DjangoV/lib/python3.10/site-packages/django/template/base.py", line 196, in compile_nodelist
    nodelist = parser.parse()
  File "/home/jobina/Documents/minproject/DRMS/DjangoV/lib/python3.10/site-packages/django/template/base.py", line 512, in parse
    self.invalid_block_tag(token, command, parse_until)
  File "/home/jobina/Documents/minproject/DRMS/DjangoV/lib/python3.10/site-packages/django/template/base.py", line 573, in invalid_block_tag
    raise self.error(
django.template.exceptions.TemplateSyntaxError: Invalid block tag on line 122: 'static'. Did you forget to register or load this tag?
Internal Server Error: /userregister/
Traceback (most recent call last):
  File "/home/jobina/Documents/minproject/DRMS/DjangoV/lib/python3.10/site-packages/django/template/base.py", line 510, in parse
    compile_func = self.tags[command]
KeyError: 'static'

During handling of the above exception, another exception occurred:

Traceback (most recent call last):
  File "/home/jobina/Documents/minproject/DRMS/DjangoV/lib/python3.10/site-packages/django/core/handlers/exception.py", line 55, in inner
    response = get_response(request)
  File "/home/jobina/Documents/minproject/DRMS/DjangoV/lib/python3.10/site-packages/django/core/handlers/base.py", line 197, in _get_response
    response = wrapped_callback(request, *callback_args, **callback_kwargs)
  File "/home/jobina/Documents/minproject/DRMS/daycation/userapp/views.py", line 342, in userregister
    return render(request, 'userregister.html')
  File "/home/jobina/Documents/minproject/DRMS/DjangoV/lib/python3.10/site-packages/django/shortcuts.py", line 25, in render
    content = loader.render_to_string(template_name, context, request, using=using)
  File "/home/jobina/Documents/minproject/DRMS/DjangoV/lib/python3.10/site-packages/django/template/loader.py", line 61, in render_to_string
    template = get_template(template_name, using=using)
  File "/home/jobina/Documents/minproject/DRMS/DjangoV/lib/python3.10/site-packages/django/template/loader.py", line 15, in get_template
    return engine.get_template(template_name)
  File "/home/jobina/Documents/minproject/DRMS/DjangoV/lib/python3.10/site-packages/django/template/backends/django.py", line 79, in get_template
    return Template(self.engine.get_template(template_name), self)
  File "/home/jobina/Documents/minproject/DRMS/DjangoV/lib/python3.10/site-packages/django/template/engine.py", line 177, in get_template
    template, origin = self.find_template(template_name)
  File "/home/jobina/Documents/minproject/DRMS/DjangoV/lib/python3.10/site-packages/django/template/engine.py", line 159, in find_template
    template = loader.get_template(name, skip=skip)
  File "/home/jobina/Documents/minproject/DRMS/DjangoV/lib/python3.10/site-packages/django/template/loaders/cached.py", line 57, in get_template
    template = super().get_template(template_name, skip)
  File "/home/jobina/Documents/minproject/DRMS/DjangoV/lib/python3.10/site-packages/django/template/loaders/base.py", line 28, in get_template
    return Template(
  File "/home/jobina/Documents/minproject/DRMS/DjangoV/lib/python3.10/site-packages/django/template/base.py", line 154, in __init__
    self.nodelist = self.compile_nodelist()
  File "/home/jobina/Documents/minproject/DRMS/DjangoV/lib/python3.10/site-packages/django/template/base.py", line 196, in compile_nodelist
    nodelist = parser.parse()
  File "/home/jobina/Documents/minproject/DRMS/DjangoV/lib/python3.10/site-packages/django/template/base.py", line 512, in parse
    self.invalid_block_tag(token, command, parse_until)
  File "/home/jobina/Documents/minproject/DRMS/DjangoV/lib/python3.10/site-packages/django/template/base.py", line 573, in invalid_block_tag
    raise self.error(
django.template.exceptions.TemplateSyntaxError: Invalid block tag on line 122: 'static'. Did you forget to register or load this tag?
Internal Server Error: /userregister/
Traceback (most recent call last):
  File "/home/jobina/Documents/minproject/DRMS/DjangoV/lib/python3.10/site-packages/django/template/base.py", line 510, in parse
    compile_func = self.tags[command]
KeyError: 'static'

During handling of the above exception, another exception occurred:

Traceback (most recent call last):
  File "/home/jobina/Documents/minproject/DRMS/DjangoV/lib/python3.10/site-packages/django/core/handlers/exception.py", line 55, in inner
    response = get_response(request)
  File "/home/jobina/Documents/minproject/DRMS/DjangoV/lib/python3.10/site-packages/django/core/handlers/base.py", line 197, in _get_response
    response = wrapped_callback(request, *callback_args, **callback_kwargs)
  File "/home/jobina/Documents/minproject/DRMS/daycation/userapp/views.py", line 342, in userregister
    return render(request, 'userregister.html')
  File "/home/jobina/Documents/minproject/DRMS/DjangoV/lib/python3.10/site-packages/django/shortcuts.py", line 25, in render
    content = loader.render_to_string(template_name, context, request, using=using)
  File "/home/jobina/Documents/minproject/DRMS/DjangoV/lib/python3.10/site-packages/django/template/loader.py", line 61, in render_to_string
    template = get_template(template_name, using=using)
  File "/home/jobina/Documents/minproject/DRMS/DjangoV/lib/python3.10/site-packages/django/template/loader.py", line 15, in get_template
    return engine.get_template(template_name)
  File "/home/jobina/Documents/minproject/DRMS/DjangoV/lib/python3.10/site-packages/django/template/backends/django.py", line 79, in get_template
    return Template(self.engine.get_template(template_name), self)
  File "/home/jobina/Documents/minproject/DRMS/DjangoV/lib/python3.10/site-packages/django/template/engine.py", line 177, in get_template
    template, origin = self.find_template(template_name)
  File "/home/jobina/Documents/minproject/DRMS/DjangoV/lib/python3.10/site-packages/django/template/engine.py", line 159, in find_template
    template = loader.get_template(name, skip=skip)
  File "/home/jobina/Documents/minproject/DRMS/DjangoV/lib/python3.10/site-packages/django/template/loaders/cached.py", line 57, in get_template
    template = super().get_template(template_name, skip)
  File "/home/jobina/Documents/minproject/DRMS/DjangoV/lib/python3.10/site-packages/django/template/loaders/base.py", line 28, in get_template
    return Template(
  File "/home/jobina/Documents/minproject/DRMS/DjangoV/lib/python3.10/site-packages/django/template/base.py", line 154, in __init__
    self.nodelist = self.compile_nodelist()
  File "/home/jobina/Documents/minproject/DRMS/DjangoV/lib/python3.10/site-packages/django/template/base.py", line 196, in compile_nodelist
    nodelist = parser.parse()
  File "/home/jobina/Documents/minproject/DRMS/DjangoV/lib/python3.10/site-packages/django/template/base.py", line 512, in parse
    self.invalid_block_tag(token, command, parse_until)
  File "/home/jobina/Documents/minproject/DRMS/DjangoV/lib/python3.10/site-packages/django/template/base.py", line 573, in invalid_block_tag
    raise self.error(
django.template.exceptions.TemplateSyntaxError: Invalid block tag on line 123: 'static'. Did you forget to register or load this tag?
Internal Server Error: /userregister/
Traceback (most recent call last):
  File "/home/jobina/Documents/minproject/DRMS/DjangoV/lib/python3.10/site-packages/django/template/base.py", line 510, in parse
    compile_func = self.tags[command]
KeyError: 'static'

During handling of the above exception, another exception occurred:

Traceback (most recent call last):
  File "/home/jobina/Documents/minproject/DRMS/DjangoV/lib/python3.10/site-packages/django/core/handlers/exception.py", line 55, in inner
    response = get_response(request)
  File "/home/jobina/Documents/minproject/DRMS/DjangoV/lib/python3.10/site-packages/django/core/handlers/base.py", line 197, in _get_response
    response = wrapped_callback(request, *callback_args, **callback_kwargs)
  File "/home/jobina/Documents/minproject/DRMS/daycation/userapp/views.py", line 342, in userregister
    return render(request, 'userregister.html')
  File "/home/jobina/Documents/minproject/DRMS/DjangoV/lib/python3.10/site-packages/django/shortcuts.py", line 25, in render
    content = loader.render_to_string(template_name, context, request, using=using)
  File "/home/jobina/Documents/minproject/DRMS/DjangoV/lib/python3.10/site-packages/django/template/loader.py", line 61, in render_to_string
    template = get_template(template_name, using=using)
  File "/home/jobina/Documents/minproject/DRMS/DjangoV/lib/python3.10/site-packages/django/template/loader.py", line 15, in get_template
    return engine.get_template(template_name)
  File "/home/jobina/Documents/minproject/DRMS/DjangoV/lib/python3.10/site-packages/django/template/backends/django.py", line 79, in get_template
    return Template(self.engine.get_template(template_name), self)
  File "/home/jobina/Documents/minproject/DRMS/DjangoV/lib/python3.10/site-packages/django/template/engine.py", line 177, in get_template
    template, origin = self.find_template(template_name)
  File "/home/jobina/Documents/minproject/DRMS/DjangoV/lib/python3.10/site-packages/django/template/engine.py", line 159, in find_template
    template = loader.get_template(name, skip=skip)
  File "/home/jobina/Documents/minproject/DRMS/DjangoV/lib/python3.10/site-packages/django/template/loaders/cached.py", line 57, in get_template
    template = super().get_template(template_name, skip)
  File "/home/jobina/Documents/minproject/DRMS/DjangoV/lib/python3.10/site-packages/django/template/loaders/base.py", line 28, in get_template
    return Template(
  File "/home/jobina/Documents/minproject/DRMS/DjangoV/lib/python3.10/site-packages/django/template/base.py", line 154, in __init__
    self.nodelist = self.compile_nodelist()
  File "/home/jobina/Documents/minproject/DRMS/DjangoV/lib/python3.10/site-packages/django/template/base.py", line 196, in compile_nodelist
    nodelist = parser.parse()
  File "/home/jobina/Documents/minproject/DRMS/DjangoV/lib/python3.10/site-packages/django/template/base.py", line 512, in parse
    self.invalid_block_tag(token, command, parse_until)
  File "/home/jobina/Documents/minproject/DRMS/DjangoV/lib/python3.10/site-packages/django/template/base.py", line 573, in invalid_block_tag
    raise self.error(
django.template.exceptions.TemplateSyntaxError: Invalid block tag on line 123: 'static'. Did you forget to register or load this tag?
Session data corrupted
Session data corrupted
Session data corrupted
Session data corrupted
Session data corrupted
Session data corrupted
Session data corrupted
Session data corrupted
Session data corrupted
Session data corrupted
Session data corrupted
Session data corrupted
Session data corrupted
Session data corrupted
Session data corrupted
Session data corrupted
Session data corrupted
Session data corrupted
Not Found: /media/default.jpg
Not Found: /media/default.jpg
Not Found: /media/default.jpg
Not Found: /media/default.jpg
Not Found: /media/default.jpg
Not Found: /media/default.jpg
Session data corrupted
Session data corrupted
Session data corrupted
Session data corrupted
Session data corrupted
Session data corrupted
Session data corrupted
Session data corrupted
Session data corrupted
Not Found: /favicon.ico
Session data corrupted
Session data corrupted
Session data corrupted
Session data corrupted
Session data corrupted
Session data corrupted
Session data corrupted
Session data corrupted
Session data corrupted
Starting new HTTPS connection (1): oauth2.googleapis.com:443
https://oauth2.googleapis.com:443 "POST /token HTTP/11" 200 None
Starting new HTTPS connection (1): oauth2.googleapis.com:443
https://oauth2.googleapis.com:443 "POST /token HTTP/11" 200 None
Internal Server Error: /about/
Traceback (most recent call last):
  File "/home/jobina/Documents/minproject/DRMS/DjangoV/lib/python3.10/site-packages/django/core/handlers/exception.py", line 55, in inner
    response = get_response(request)
  File "/home/jobina/Documents/minproject/DRMS/DjangoV/lib/python3.10/site-packages/django/core/handlers/base.py", line 197, in _get_response
    response = wrapped_callback(request, *callback_args, **callback_kwargs)
  File "/home/jobina/Documents/minproject/DRMS/daycation/userapp/views.py", line 96, in about
    return render(request, 'about.html')
  File "/home/jobina/Documents/minproject/DRMS/DjangoV/lib/python3.10/site-packages/django/shortcuts.py", line 25, in render
    content = loader.render_to_string(template_name, context, request, using=using)
  File "/home/jobina/Documents/minproject/DRMS/DjangoV/lib/python3.10/site-packages/django/template/loader.py", line 62, in render_to_string
    return template.render(context, request)
  File "/home/jobina/Documents/minproject/DRMS/DjangoV/lib/python3.10/site-packages/django/template/backends/django.py", line 107, in render
    return self.template.render(context)
  File "/home/jobina/Documents/minproject/DRMS/DjangoV/lib/python3.10/site-packages/django/template/base.py", line 171, in render
    return self._render(context)
  File "/home/jobina/Documents/minproject/DRMS/DjangoV/lib/python3.10/site-packages/django/template/base.py", line 163, in _render
    return self.nodelist.render(context)
  File "/home/jobina/Documents/minproject/DRMS/DjangoV/lib/python3.10/site-packages/django/template/base.py", line 1008, in render
    return SafeString("".join([node.render_annotated(context) for node in self]))
  File "/home/jobina/Documents/minproject/DRMS/DjangoV/lib/python3.10/site-packages/django/template/base.py", line 1008, in <listcomp>
    return SafeString("".join([node.render_annotated(context) for node in self]))
  File "/home/jobina/Documents/minproject/DRMS/DjangoV/lib/python3.10/site-packages/django/template/base.py", line 969, in render_annotated
    return self.render(context)
  File "/home/jobina/Documents/minproject/DRMS/DjangoV/lib/python3.10/site-packages/django/template/loader_tags.py", line 159, in render
    return compiled_parent._render(context)
  File "/home/jobina/Documents/minproject/DRMS/DjangoV/lib/python3.10/site-packages/django/template/base.py", line 163, in _render
    return self.nodelist.render(context)
  File "/home/jobina/Documents/minproject/DRMS/DjangoV/lib/python3.10/site-packages/django/template/base.py", line 1008, in render
    return SafeString("".join([node.render_annotated(context) for node in self]))
  File "/home/jobina/Documents/minproject/DRMS/DjangoV/lib/python3.10/site-packages/django/template/base.py", line 1008, in <listcomp>
    return SafeString("".join([node.render_annotated(context) for node in self]))
  File "/home/jobina/Documents/minproject/DRMS/DjangoV/lib/python3.10/site-packages/django/template/base.py", line 969, in render_annotated
    return self.render(context)
  File "/home/jobina/Documents/minproject/DRMS/DjangoV/lib/python3.10/site-packages/django/template/defaulttags.py", line 480, in render
    url = reverse(view_name, args=args, kwargs=kwargs, current_app=current_app)
  File "/home/jobina/Documents/minproject/DRMS/DjangoV/lib/python3.10/site-packages/django/urls/base.py", line 88, in reverse
    return resolver._reverse_with_prefix(view, prefix, *args, **kwargs)
  File "/home/jobina/Documents/minproject/DRMS/DjangoV/lib/python3.10/site-packages/django/urls/resolvers.py", line 831, in _reverse_with_prefix
    raise NoReverseMatch(msg)
django.urls.exceptions.NoReverseMatch: Reverse for 'packages' not found. 'packages' is not a valid view function or pattern name.
Session data corrupted
Session data corrupted
Session data corrupted
Session data corrupted
Session data corrupted
Session data corrupted
Session data corrupted
Session data corrupted
Session data corrupted
Session data corrupted
Session data corrupted
Session data corrupted
Session data corrupted
Session data corrupted
Internal Server Error: /blog/
Traceback (most recent call last):
  File "/home/jobina/Documents/minproject/DRMS/DjangoV/lib/python3.10/site-packages/django/core/handlers/exception.py", line 55, in inner
    response = get_response(request)
  File "/home/jobina/Documents/minproject/DRMS/DjangoV/lib/python3.10/site-packages/django/core/handlers/base.py", line 197, in _get_response
    response = wrapped_callback(request, *callback_args, **callback_kwargs)
  File "/home/jobina/Documents/minproject/DRMS/daycation/userapp/views.py", line 99, in blog
    return render(request, 'blog.html')
  File "/home/jobina/Documents/minproject/DRMS/DjangoV/lib/python3.10/site-packages/django/shortcuts.py", line 25, in render
    content = loader.render_to_string(template_name, context, request, using=using)
  File "/home/jobina/Documents/minproject/DRMS/DjangoV/lib/python3.10/site-packages/django/template/loader.py", line 62, in render_to_string
    return template.render(context, request)
  File "/home/jobina/Documents/minproject/DRMS/DjangoV/lib/python3.10/site-packages/django/template/backends/django.py", line 107, in render
    return self.template.render(context)
  File "/home/jobina/Documents/minproject/DRMS/DjangoV/lib/python3.10/site-packages/django/template/base.py", line 171, in render
    return self._render(context)
  File "/home/jobina/Documents/minproject/DRMS/DjangoV/lib/python3.10/site-packages/django/template/base.py", line 163, in _render
    return self.nodelist.render(context)
  File "/home/jobina/Documents/minproject/DRMS/DjangoV/lib/python3.10/site-packages/django/template/base.py", line 1008, in render
    return SafeString("".join([node.render_annotated(context) for node in self]))
  File "/home/jobina/Documents/minproject/DRMS/DjangoV/lib/python3.10/site-packages/django/template/base.py", line 1008, in <listcomp>
    return SafeString("".join([node.render_annotated(context) for node in self]))
  File "/home/jobina/Documents/minproject/DRMS/DjangoV/lib/python3.10/site-packages/django/template/base.py", line 969, in render_annotated
    return self.render(context)
  File "/home/jobina/Documents/minproject/DRMS/DjangoV/lib/python3.10/site-packages/django/template/loader_tags.py", line 159, in render
    return compiled_parent._render(context)
  File "/home/jobina/Documents/minproject/DRMS/DjangoV/lib/python3.10/site-packages/django/template/base.py", line 163, in _render
    return self.nodelist.render(context)
  File "/home/jobina/Documents/minproject/DRMS/DjangoV/lib/python3.10/site-packages/django/template/base.py", line 1008, in render
    return SafeString("".join([node.render_annotated(context) for node in self]))
  File "/home/jobina/Documents/minproject/DRMS/DjangoV/lib/python3.10/site-packages/django/template/base.py", line 1008, in <listcomp>
    return SafeString("".join([node.render_annotated(context) for node in self]))
  File "/home/jobina/Documents/minproject/DRMS/DjangoV/lib/python3.10/site-packages/django/template/base.py", line 969, in render_annotated
    return self.render(context)
  File "/home/jobina/Documents/minproject/DRMS/DjangoV/lib/python3.10/site-packages/django/template/defaulttags.py", line 480, in render
    url = reverse(view_name, args=args, kwargs=kwargs, current_app=current_app)
  File "/home/jobina/Documents/minproject/DRMS/DjangoV/lib/python3.10/site-packages/django/urls/base.py", line 88, in reverse
    return resolver._reverse_with_prefix(view, prefix, *args, **kwargs)
  File "/home/jobina/Documents/minproject/DRMS/DjangoV/lib/python3.10/site-packages/django/urls/resolvers.py", line 831, in _reverse_with_prefix
    raise NoReverseMatch(msg)
django.urls.exceptions.NoReverseMatch: Reverse for 'packages' not found. 'packages' is not a valid view function or pattern name.
Internal Server Error: /contact/
Traceback (most recent call last):
  File "/home/jobina/Documents/minproject/DRMS/DjangoV/lib/python3.10/site-packages/django/core/handlers/exception.py", line 55, in inner
    response = get_response(request)
  File "/home/jobina/Documents/minproject/DRMS/DjangoV/lib/python3.10/site-packages/django/core/handlers/base.py", line 197, in _get_response
    response = wrapped_callback(request, *callback_args, **callback_kwargs)
  File "/home/jobina/Documents/minproject/DRMS/daycation/userapp/views.py", line 201, in contact
    return render(request, 'contact.html')
  File "/home/jobina/Documents/minproject/DRMS/DjangoV/lib/python3.10/site-packages/django/shortcuts.py", line 25, in render
    content = loader.render_to_string(template_name, context, request, using=using)
  File "/home/jobina/Documents/minproject/DRMS/DjangoV/lib/python3.10/site-packages/django/template/loader.py", line 62, in render_to_string
    return template.render(context, request)
  File "/home/jobina/Documents/minproject/DRMS/DjangoV/lib/python3.10/site-packages/django/template/backends/django.py", line 107, in render
    return self.template.render(context)
  File "/home/jobina/Documents/minproject/DRMS/DjangoV/lib/python3.10/site-packages/django/template/base.py", line 171, in render
    return self._render(context)
  File "/home/jobina/Documents/minproject/DRMS/DjangoV/lib/python3.10/site-packages/django/template/base.py", line 163, in _render
    return self.nodelist.render(context)
  File "/home/jobina/Documents/minproject/DRMS/DjangoV/lib/python3.10/site-packages/django/template/base.py", line 1008, in render
    return SafeString("".join([node.render_annotated(context) for node in self]))
  File "/home/jobina/Documents/minproject/DRMS/DjangoV/lib/python3.10/site-packages/django/template/base.py", line 1008, in <listcomp>
    return SafeString("".join([node.render_annotated(context) for node in self]))
  File "/home/jobina/Documents/minproject/DRMS/DjangoV/lib/python3.10/site-packages/django/template/base.py", line 969, in render_annotated
    return self.render(context)
  File "/home/jobina/Documents/minproject/DRMS/DjangoV/lib/python3.10/site-packages/django/template/loader_tags.py", line 159, in render
    return compiled_parent._render(context)
  File "/home/jobina/Documents/minproject/DRMS/DjangoV/lib/python3.10/site-packages/django/template/base.py", line 163, in _render
    return self.nodelist.render(context)
  File "/home/jobina/Documents/minproject/DRMS/DjangoV/lib/python3.10/site-packages/django/template/base.py", line 1008, in render
    return SafeString("".join([node.render_annotated(context) for node in self]))
  File "/home/jobina/Documents/minproject/DRMS/DjangoV/lib/python3.10/site-packages/django/template/base.py", line 1008, in <listcomp>
    return SafeString("".join([node.render_annotated(context) for node in self]))
  File "/home/jobina/Documents/minproject/DRMS/DjangoV/lib/python3.10/site-packages/django/template/base.py", line 969, in render_annotated
    return self.render(context)
  File "/home/jobina/Documents/minproject/DRMS/DjangoV/lib/python3.10/site-packages/django/template/defaulttags.py", line 480, in render
    url = reverse(view_name, args=args, kwargs=kwargs, current_app=current_app)
  File "/home/jobina/Documents/minproject/DRMS/DjangoV/lib/python3.10/site-packages/django/urls/base.py", line 88, in reverse
    return resolver._reverse_with_prefix(view, prefix, *args, **kwargs)
  File "/home/jobina/Documents/minproject/DRMS/DjangoV/lib/python3.10/site-packages/django/urls/resolvers.py", line 831, in _reverse_with_prefix
    raise NoReverseMatch(msg)
django.urls.exceptions.NoReverseMatch: Reverse for 'packages' not found. 'packages' is not a valid view function or pattern name.
Internal Server Error: /userindex/
Traceback (most recent call last):
  File "/home/jobina/Documents/minproject/DRMS/DjangoV/lib/python3.10/site-packages/django/core/handlers/exception.py", line 55, in inner
    response = get_response(request)
  File "/home/jobina/Documents/minproject/DRMS/DjangoV/lib/python3.10/site-packages/django/core/handlers/base.py", line 197, in _get_response
    response = wrapped_callback(request, *callback_args, **callback_kwargs)
  File "/home/jobina/Documents/minproject/DRMS/daycation/userapp/views.py", line 215, in userindex
    return render(request, 'userindex.html', context)
  File "/home/jobina/Documents/minproject/DRMS/DjangoV/lib/python3.10/site-packages/django/shortcuts.py", line 25, in render
    content = loader.render_to_string(template_name, context, request, using=using)
  File "/home/jobina/Documents/minproject/DRMS/DjangoV/lib/python3.10/site-packages/django/template/loader.py", line 62, in render_to_string
    return template.render(context, request)
  File "/home/jobina/Documents/minproject/DRMS/DjangoV/lib/python3.10/site-packages/django/template/backends/django.py", line 107, in render
    return self.template.render(context)
  File "/home/jobina/Documents/minproject/DRMS/DjangoV/lib/python3.10/site-packages/django/template/base.py", line 171, in render
    return self._render(context)
  File "/home/jobina/Documents/minproject/DRMS/DjangoV/lib/python3.10/site-packages/django/template/base.py", line 163, in _render
    return self.nodelist.render(context)
  File "/home/jobina/Documents/minproject/DRMS/DjangoV/lib/python3.10/site-packages/django/template/base.py", line 1008, in render
    return SafeString("".join([node.render_annotated(context) for node in self]))
  File "/home/jobina/Documents/minproject/DRMS/DjangoV/lib/python3.10/site-packages/django/template/base.py", line 1008, in <listcomp>
    return SafeString("".join([node.render_annotated(context) for node in self]))
  File "/home/jobina/Documents/minproject/DRMS/DjangoV/lib/python3.10/site-packages/django/template/base.py", line 969, in render_annotated
    return self.render(context)
  File "/home/jobina/Documents/minproject/DRMS/DjangoV/lib/python3.10/site-packages/django/template/defaulttags.py", line 327, in render
    return nodelist.render(context)
  File "/home/jobina/Documents/minproject/DRMS/DjangoV/lib/python3.10/site-packages/django/template/base.py", line 1008, in render
    return SafeString("".join([node.render_annotated(context) for node in self]))
  File "/home/jobina/Documents/minproject/DRMS/DjangoV/lib/python3.10/site-packages/django/template/base.py", line 1008, in <listcomp>
    return SafeString("".join([node.render_annotated(context) for node in self]))
  File "/home/jobina/Documents/minproject/DRMS/DjangoV/lib/python3.10/site-packages/django/template/base.py", line 969, in render_annotated
    return self.render(context)
  File "/home/jobina/Documents/minproject/DRMS/DjangoV/lib/python3.10/site-packages/django/template/defaulttags.py", line 480, in render
    url = reverse(view_name, args=args, kwargs=kwargs, current_app=current_app)
  File "/home/jobina/Documents/minproject/DRMS/DjangoV/lib/python3.10/site-packages/django/urls/base.py", line 88, in reverse
    return resolver._reverse_with_prefix(view, prefix, *args, **kwargs)
  File "/home/jobina/Documents/minproject/DRMS/DjangoV/lib/python3.10/site-packages/django/urls/resolvers.py", line 831, in _reverse_with_prefix
    raise NoReverseMatch(msg)
django.urls.exceptions.NoReverseMatch: Reverse for 'recommended_packages' not found. 'recommended_packages' is not a valid view function or pattern name.
Internal Server Error: /userindex/
Traceback (most recent call last):
  File "/home/jobina/Documents/minproject/DRMS/DjangoV/lib/python3.10/site-packages/django/template/base.py", line 510, in parse
    compile_func = self.tags[command]
KeyError: 'endblock'

During handling of the above exception, another exception occurred:

Traceback (most recent call last):
  File "/home/jobina/Documents/minproject/DRMS/DjangoV/lib/python3.10/site-packages/django/core/handlers/exception.py", line 55, in inner
    response = get_response(request)
  File "/home/jobina/Documents/minproject/DRMS/DjangoV/lib/python3.10/site-packages/django/core/handlers/base.py", line 197, in _get_response
    response = wrapped_callback(request, *callback_args, **callback_kwargs)
  File "/home/jobina/Documents/minproject/DRMS/daycation/userapp/views.py", line 215, in userindex
    return render(request, 'userindex.html', context)
  File "/home/jobina/Documents/minproject/DRMS/DjangoV/lib/python3.10/site-packages/django/shortcuts.py", line 25, in render
    content = loader.render_to_string(template_name, context, request, using=using)
  File "/home/jobina/Documents/minproject/DRMS/DjangoV/lib/python3.10/site-packages/django/template/loader.py", line 61, in render_to_string
    template = get_template(template_name, using=using)
  File "/home/jobina/Documents/minproject/DRMS/DjangoV/lib/python3.10/site-packages/django/template/loader.py", line 15, in get_template
    return engine.get_template(template_name)
  File "/home/jobina/Documents/minproject/DRMS/DjangoV/lib/python3.10/site-packages/django/template/backends/django.py", line 79, in get_template
    return Template(self.engine.get_template(template_name), self)
  File "/home/jobina/Documents/minproject/DRMS/DjangoV/lib/python3.10/site-packages/django/template/engine.py", line 177, in get_template
    template, origin = self.find_template(template_name)
  File "/home/jobina/Documents/minproject/DRMS/DjangoV/lib/python3.10/site-packages/django/template/engine.py", line 159, in find_template
    template = loader.get_template(name, skip=skip)
  File "/home/jobina/Documents/minproject/DRMS/DjangoV/lib/python3.10/site-packages/django/template/loaders/cached.py", line 57, in get_template
    template = super().get_template(template_name, skip)
  File "/home/jobina/Documents/minproject/DRMS/DjangoV/lib/python3.10/site-packages/django/template/loaders/base.py", line 28, in get_template
    return Template(
  File "/home/jobina/Documents/minproject/DRMS/DjangoV/lib/python3.10/site-packages/django/template/base.py", line 154, in __init__
    self.nodelist = self.compile_nodelist()
  File "/home/jobina/Documents/minproject/DRMS/DjangoV/lib/python3.10/site-packages/django/template/base.py", line 196, in compile_nodelist
    nodelist = parser.parse()
  File "/home/jobina/Documents/minproject/DRMS/DjangoV/lib/python3.10/site-packages/django/template/base.py", line 512, in parse
    self.invalid_block_tag(token, command, parse_until)
  File "/home/jobina/Documents/minproject/DRMS/DjangoV/lib/python3.10/site-packages/django/template/base.py", line 573, in invalid_block_tag
    raise self.error(
django.template.exceptions.TemplateSyntaxError: Invalid block tag on line 390: 'endblock'. Did you forget to register or load this tag?
Not Found: /userindex/path_to_your_logo.png
Not Found: /userindex/path_to_profile_pic.jpg
Internal Server Error: /userindex/
Traceback (most recent call last):
  File "/home/jobina/Documents/minproject/DRMS/DjangoV/lib/python3.10/site-packages/django/core/handlers/exception.py", line 55, in inner
    response = get_response(request)
  File "/home/jobina/Documents/minproject/DRMS/DjangoV/lib/python3.10/site-packages/django/core/handlers/base.py", line 197, in _get_response
    response = wrapped_callback(request, *callback_args, **callback_kwargs)
  File "/home/jobina/Documents/minproject/DRMS/daycation/userapp/views.py", line 215, in userindex
    return render(request, 'userindex.html', context)
  File "/home/jobina/Documents/minproject/DRMS/DjangoV/lib/python3.10/site-packages/django/shortcuts.py", line 25, in render
    content = loader.render_to_string(template_name, context, request, using=using)
  File "/home/jobina/Documents/minproject/DRMS/DjangoV/lib/python3.10/site-packages/django/template/loader.py", line 62, in render_to_string
    return template.render(context, request)
  File "/home/jobina/Documents/minproject/DRMS/DjangoV/lib/python3.10/site-packages/django/template/backends/django.py", line 107, in render
    return self.template.render(context)
  File "/home/jobina/Documents/minproject/DRMS/DjangoV/lib/python3.10/site-packages/django/template/base.py", line 171, in render
    return self._render(context)
  File "/home/jobina/Documents/minproject/DRMS/DjangoV/lib/python3.10/site-packages/django/template/base.py", line 163, in _render
    return self.nodelist.render(context)
  File "/home/jobina/Documents/minproject/DRMS/DjangoV/lib/python3.10/site-packages/django/template/base.py", line 1008, in render
    return SafeString("".join([node.render_annotated(context) for node in self]))
  File "/home/jobina/Documents/minproject/DRMS/DjangoV/lib/python3.10/site-packages/django/template/base.py", line 1008, in <listcomp>
    return SafeString("".join([node.render_annotated(context) for node in self]))
  File "/home/jobina/Documents/minproject/DRMS/DjangoV/lib/python3.10/site-packages/django/template/base.py", line 969, in render_annotated
    return self.render(context)
  File "/home/jobina/Documents/minproject/DRMS/DjangoV/lib/python3.10/site-packages/django/template/defaulttags.py", line 480, in render
    url = reverse(view_name, args=args, kwargs=kwargs, current_app=current_app)
  File "/home/jobina/Documents/minproject/DRMS/DjangoV/lib/python3.10/site-packages/django/urls/base.py", line 88, in reverse
    return resolver._reverse_with_prefix(view, prefix, *args, **kwargs)
  File "/home/jobina/Documents/minproject/DRMS/DjangoV/lib/python3.10/site-packages/django/urls/resolvers.py", line 831, in _reverse_with_prefix
    raise NoReverseMatch(msg)
django.urls.exceptions.NoReverseMatch: Reverse for 'staycation_packages' not found. 'staycation_packages' is not a valid view function or pattern name.
Internal Server Error: /userindex/
Traceback (most recent call last):
  File "/home/jobina/Documents/minproject/DRMS/DjangoV/lib/python3.10/site-packages/django/core/handlers/exception.py", line 55, in inner
    response = get_response(request)
  File "/home/jobina/Documents/minproject/DRMS/DjangoV/lib/python3.10/site-packages/django/core/handlers/base.py", line 197, in _get_response
    response = wrapped_callback(request, *callback_args, **callback_kwargs)
  File "/home/jobina/Documents/minproject/DRMS/daycation/userapp/views.py", line 215, in userindex
    return render(request, 'userindex.html', context)
  File "/home/jobina/Documents/minproject/DRMS/DjangoV/lib/python3.10/site-packages/django/shortcuts.py", line 25, in render
    content = loader.render_to_string(template_name, context, request, using=using)
  File "/home/jobina/Documents/minproject/DRMS/DjangoV/lib/python3.10/site-packages/django/template/loader.py", line 62, in render_to_string
    return template.render(context, request)
  File "/home/jobina/Documents/minproject/DRMS/DjangoV/lib/python3.10/site-packages/django/template/backends/django.py", line 107, in render
    return self.template.render(context)
  File "/home/jobina/Documents/minproject/DRMS/DjangoV/lib/python3.10/site-packages/django/template/base.py", line 171, in render
    return self._render(context)
  File "/home/jobina/Documents/minproject/DRMS/DjangoV/lib/python3.10/site-packages/django/template/base.py", line 163, in _render
    return self.nodelist.render(context)
  File "/home/jobina/Documents/minproject/DRMS/DjangoV/lib/python3.10/site-packages/django/template/base.py", line 1008, in render
    return SafeString("".join([node.render_annotated(context) for node in self]))
  File "/home/jobina/Documents/minproject/DRMS/DjangoV/lib/python3.10/site-packages/django/template/base.py", line 1008, in <listcomp>
    return SafeString("".join([node.render_annotated(context) for node in self]))
  File "/home/jobina/Documents/minproject/DRMS/DjangoV/lib/python3.10/site-packages/django/template/base.py", line 969, in render_annotated
    return self.render(context)
  File "/home/jobina/Documents/minproject/DRMS/DjangoV/lib/python3.10/site-packages/django/template/defaulttags.py", line 480, in render
    url = reverse(view_name, args=args, kwargs=kwargs, current_app=current_app)
  File "/home/jobina/Documents/minproject/DRMS/DjangoV/lib/python3.10/site-packages/django/urls/base.py", line 88, in reverse
    return resolver._reverse_with_prefix(view, prefix, *args, **kwargs)
  File "/home/jobina/Documents/minproject/DRMS/DjangoV/lib/python3.10/site-packages/django/urls/resolvers.py", line 831, in _reverse_with_prefix
    raise NoReverseMatch(msg)
django.urls.exceptions.NoReverseMatch: Reverse for 'user' not found. 'user' is not a valid view function or pattern name.
Internal Server Error: /userindex/
Traceback (most recent call last):
  File "/home/jobina/Documents/minproject/DRMS/DjangoV/lib/python3.10/site-packages/django/template/base.py", line 510, in parse
    compile_func = self.tags[command]
KeyError: 'endblock'

During handling of the above exception, another exception occurred:

Traceback (most recent call last):
  File "/home/jobina/Documents/minproject/DRMS/DjangoV/lib/python3.10/site-packages/django/core/handlers/exception.py", line 55, in inner
    response = get_response(request)
  File "/home/jobina/Documents/minproject/DRMS/DjangoV/lib/python3.10/site-packages/django/core/handlers/base.py", line 197, in _get_response
    response = wrapped_callback(request, *callback_args, **callback_kwargs)
  File "/home/jobina/Documents/minproject/DRMS/daycation/userapp/views.py", line 215, in userindex
    return render(request, 'userindex.html', context)
  File "/home/jobina/Documents/minproject/DRMS/DjangoV/lib/python3.10/site-packages/django/shortcuts.py", line 25, in render
    content = loader.render_to_string(template_name, context, request, using=using)
  File "/home/jobina/Documents/minproject/DRMS/DjangoV/lib/python3.10/site-packages/django/template/loader.py", line 61, in render_to_string
    template = get_template(template_name, using=using)
  File "/home/jobina/Documents/minproject/DRMS/DjangoV/lib/python3.10/site-packages/django/template/loader.py", line 15, in get_template
    return engine.get_template(template_name)
  File "/home/jobina/Documents/minproject/DRMS/DjangoV/lib/python3.10/site-packages/django/template/backends/django.py", line 79, in get_template
    return Template(self.engine.get_template(template_name), self)
  File "/home/jobina/Documents/minproject/DRMS/DjangoV/lib/python3.10/site-packages/django/template/engine.py", line 177, in get_template
    template, origin = self.find_template(template_name)
  File "/home/jobina/Documents/minproject/DRMS/DjangoV/lib/python3.10/site-packages/django/template/engine.py", line 159, in find_template
    template = loader.get_template(name, skip=skip)
  File "/home/jobina/Documents/minproject/DRMS/DjangoV/lib/python3.10/site-packages/django/template/loaders/cached.py", line 57, in get_template
    template = super().get_template(template_name, skip)
  File "/home/jobina/Documents/minproject/DRMS/DjangoV/lib/python3.10/site-packages/django/template/loaders/base.py", line 28, in get_template
    return Template(
  File "/home/jobina/Documents/minproject/DRMS/DjangoV/lib/python3.10/site-packages/django/template/base.py", line 154, in __init__
    self.nodelist = self.compile_nodelist()
  File "/home/jobina/Documents/minproject/DRMS/DjangoV/lib/python3.10/site-packages/django/template/base.py", line 196, in compile_nodelist
    nodelist = parser.parse()
  File "/home/jobina/Documents/minproject/DRMS/DjangoV/lib/python3.10/site-packages/django/template/base.py", line 512, in parse
    self.invalid_block_tag(token, command, parse_until)
  File "/home/jobina/Documents/minproject/DRMS/DjangoV/lib/python3.10/site-packages/django/template/base.py", line 573, in invalid_block_tag
    raise self.error(
django.template.exceptions.TemplateSyntaxError: Invalid block tag on line 485: 'endblock'. Did you forget to register or load this tag?
/home/jobina/Documents/minproject/DRMS/daycation/userapp/views.py changed, reloading.
Watching for file changes with StatReloader
Session data corrupted
Session data corrupted
Session data corrupted
Session data corrupted
Session data corrupted
Session data corrupted
Session data corrupted
Session data corrupted
Session data corrupted
Watching for file changes with StatReloader
Session data corrupted
Session data corrupted
Not Found: /favicon.ico
Session data corrupted
Session data corrupted
Session data corrupted
Session data corrupted
Session data corrupted
Session data corrupted
Session data corrupted
Session data corrupted
Watching for file changes with StatReloader
Session data corrupted
Not Found: /favicon.ico
Session data corrupted
Session data corrupted
Session data corrupted
Session data corrupted
Session data corrupted
Internal Server Error: /viewprofile/
Traceback (most recent call last):
  File "/home/jobina/Documents/minproject/DRMS/DjangoV/lib/python3.10/site-packages/django/core/handlers/exception.py", line 55, in inner
    response = get_response(request)
  File "/home/jobina/Documents/minproject/DRMS/DjangoV/lib/python3.10/site-packages/django/core/handlers/base.py", line 197, in _get_response
    response = wrapped_callback(request, *callback_args, **callback_kwargs)
  File "/home/jobina/Documents/minproject/DRMS/daycation/userapp/views.py", line 352, in viewprofile
    return render(request, 'viewprofile.html', {'user': user})
  File "/home/jobina/Documents/minproject/DRMS/DjangoV/lib/python3.10/site-packages/django/shortcuts.py", line 25, in render
    content = loader.render_to_string(template_name, context, request, using=using)
  File "/home/jobina/Documents/minproject/DRMS/DjangoV/lib/python3.10/site-packages/django/template/loader.py", line 62, in render_to_string
    return template.render(context, request)
  File "/home/jobina/Documents/minproject/DRMS/DjangoV/lib/python3.10/site-packages/django/template/backends/django.py", line 107, in render
    return self.template.render(context)
  File "/home/jobina/Documents/minproject/DRMS/DjangoV/lib/python3.10/site-packages/django/template/base.py", line 171, in render
    return self._render(context)
  File "/home/jobina/Documents/minproject/DRMS/DjangoV/lib/python3.10/site-packages/django/template/base.py", line 163, in _render
    return self.nodelist.render(context)
  File "/home/jobina/Documents/minproject/DRMS/DjangoV/lib/python3.10/site-packages/django/template/base.py", line 1008, in render
    return SafeString("".join([node.render_annotated(context) for node in self]))
  File "/home/jobina/Documents/minproject/DRMS/DjangoV/lib/python3.10/site-packages/django/template/base.py", line 1008, in <listcomp>
    return SafeString("".join([node.render_annotated(context) for node in self]))
  File "/home/jobina/Documents/minproject/DRMS/DjangoV/lib/python3.10/site-packages/django/template/base.py", line 969, in render_annotated
    return self.render(context)
  File "/home/jobina/Documents/minproject/DRMS/DjangoV/lib/python3.10/site-packages/django/template/loader_tags.py", line 159, in render
    return compiled_parent._render(context)
  File "/home/jobina/Documents/minproject/DRMS/DjangoV/lib/python3.10/site-packages/django/template/base.py", line 163, in _render
    return self.nodelist.render(context)
  File "/home/jobina/Documents/minproject/DRMS/DjangoV/lib/python3.10/site-packages/django/template/base.py", line 1008, in render
    return SafeString("".join([node.render_annotated(context) for node in self]))
  File "/home/jobina/Documents/minproject/DRMS/DjangoV/lib/python3.10/site-packages/django/template/base.py", line 1008, in <listcomp>
    return SafeString("".join([node.render_annotated(context) for node in self]))
  File "/home/jobina/Documents/minproject/DRMS/DjangoV/lib/python3.10/site-packages/django/template/base.py", line 969, in render_annotated
    return self.render(context)
  File "/home/jobina/Documents/minproject/DRMS/DjangoV/lib/python3.10/site-packages/django/template/loader_tags.py", line 65, in render
    result = block.nodelist.render(context)
  File "/home/jobina/Documents/minproject/DRMS/DjangoV/lib/python3.10/site-packages/django/template/base.py", line 1008, in render
    return SafeString("".join([node.render_annotated(context) for node in self]))
  File "/home/jobina/Documents/minproject/DRMS/DjangoV/lib/python3.10/site-packages/django/template/base.py", line 1008, in <listcomp>
    return SafeString("".join([node.render_annotated(context) for node in self]))
  File "/home/jobina/Documents/minproject/DRMS/DjangoV/lib/python3.10/site-packages/django/template/base.py", line 969, in render_annotated
    return self.render(context)
  File "/home/jobina/Documents/minproject/DRMS/DjangoV/lib/python3.10/site-packages/django/template/defaulttags.py", line 480, in render
    url = reverse(view_name, args=args, kwargs=kwargs, current_app=current_app)
  File "/home/jobina/Documents/minproject/DRMS/DjangoV/lib/python3.10/site-packages/django/urls/base.py", line 88, in reverse
    return resolver._reverse_with_prefix(view, prefix, *args, **kwargs)
  File "/home/jobina/Documents/minproject/DRMS/DjangoV/lib/python3.10/site-packages/django/urls/resolvers.py", line 831, in _reverse_with_prefix
    raise NoReverseMatch(msg)
django.urls.exceptions.NoReverseMatch: Reverse for 'edit_profile' not found. 'edit_profile' is not a valid view function or pattern name.
Session data corrupted
Session data corrupted
Session data corrupted
Session data corrupted
Session data corrupted
Not Found: /favicon.ico
Processing booking for package 13
Starting new HTTPS connection (1): api.razorpay.com:443
https://api.razorpay.com:443 "POST /v1/orders HTTP/11" 200 215
Bad Request: /verify-payment/
/home/jobina/Documents/minproject/DRMS/daycation/userapp/models.py changed, reloading.
Watching for file changes with StatReloader
Watching for file changes with StatReloader
/home/jobina/Documents/minproject/DRMS/daycation/userapp/views.py changed, reloading.
Watching for file changes with StatReloader
/home/jobina/Documents/minproject/DRMS/daycation/userapp/views.py changed, reloading.
Watching for file changes with StatReloader
/home/jobina/Documents/minproject/DRMS/daycation/userapp/views.py changed, reloading.
Watching for file changes with StatReloader
/home/jobina/Documents/minproject/DRMS/daycation/userapp/views.py changed, reloading.
Watching for file changes with StatReloader
/home/jobina/Documents/minproject/DRMS/daycation/userapp/urls.py changed, reloading.
Watching for file changes with StatReloader
Session data corrupted
Internal Server Error: /userregister/
Traceback (most recent call last):
  File "/home/jobina/Documents/minproject/DRMS/DjangoV/lib/python3.10/site-packages/django/core/handlers/exception.py", line 55, in inner
    response = get_response(request)
  File "/home/jobina/Documents/minproject/DRMS/DjangoV/lib/python3.10/site-packages/django/core/handlers/base.py", line 197, in _get_response
    response = wrapped_callback(request, *callback_args, **callback_kwargs)
  File "/home/jobina/Documents/minproject/DRMS/daycation/userapp/views.py", line 380, in userregister
    return render(request, 'userregister.html')
  File "/home/jobina/Documents/minproject/DRMS/DjangoV/lib/python3.10/site-packages/django/shortcuts.py", line 25, in render
    content = loader.render_to_string(template_name, context, request, using=using)
  File "/home/jobina/Documents/minproject/DRMS/DjangoV/lib/python3.10/site-packages/django/template/loader.py", line 62, in render_to_string
    return template.render(context, request)
  File "/home/jobina/Documents/minproject/DRMS/DjangoV/lib/python3.10/site-packages/django/template/backends/django.py", line 107, in render
    return self.template.render(context)
  File "/home/jobina/Documents/minproject/DRMS/DjangoV/lib/python3.10/site-packages/django/template/base.py", line 171, in render
    return self._render(context)
  File "/home/jobina/Documents/minproject/DRMS/DjangoV/lib/python3.10/site-packages/django/template/base.py", line 163, in _render
    return self.nodelist.render(context)
  File "/home/jobina/Documents/minproject/DRMS/DjangoV/lib/python3.10/site-packages/django/template/base.py", line 1008, in render
    return SafeString("".join([node.render_annotated(context) for node in self]))
  File "/home/jobina/Documents/minproject/DRMS/DjangoV/lib/python3.10/site-packages/django/template/base.py", line 1008, in <listcomp>
    return SafeString("".join([node.render_annotated(context) for node in self]))
  File "/home/jobina/Documents/minproject/DRMS/DjangoV/lib/python3.10/site-packages/django/template/base.py", line 969, in render_annotated
    return self.render(context)
  File "/home/jobina/Documents/minproject/DRMS/DjangoV/lib/python3.10/site-packages/django/template/defaulttags.py", line 480, in render
    url = reverse(view_name, args=args, kwargs=kwargs, current_app=current_app)
  File "/home/jobina/Documents/minproject/DRMS/DjangoV/lib/python3.10/site-packages/django/urls/base.py", line 88, in reverse
    return resolver._reverse_with_prefix(view, prefix, *args, **kwargs)
  File "/home/jobina/Documents/minproject/DRMS/DjangoV/lib/python3.10/site-packages/django/urls/resolvers.py", line 831, in _reverse_with_prefix
    raise NoReverseMatch(msg)
django.urls.exceptions.NoReverseMatch: Reverse for 'check_email' not found. 'check_email' is not a valid view function or pattern name.
